File: XRD/NaBr.ras
*RAS_DATA_START
*RAS_HEADER_START
*DISP_FMT_X "%.2f"
*DISP_FMT_Y "%.0f"
*DISP_FULLSCALE "2113.2000000000"
*DISP_LINE_COLOR "255.0000000000"
*DISP_LINE_STYLE "0.0000000000"
*DISP_LINE_WIDTH "0.2500000000"
*DISP_NOTE "Collected Data-2"
*DISP_OFFSET_Y "0.0000000000"
*DISP_PEAKSEARCH_UNIT_Y "COUNTS"
*DISP_RANGE_BOTTOM "0.0000000000"
*DISP_RANGE_LEFT "2.0100000000"
*DISP_RANGE_LOGCUTOFF "0.0100000000"
*DISP_RANGE_RIGHT "69.9900000000"
*DISP_RANGE_TOP "2113.2000000000"
*DISP_SCALE_MODE_Y "0.0000000000"
*DISP_TAB_NAME "Theta/2-Theta"
*DISP_TITLE_Y "Intensity"
*DISP_UNIT_Y "COUNTS"
*DISP_WINDOW_NAME "MSG_MACROENGINE"
*FILE_COMMENT " "
*FILE_MD5 ""
*FILE_MEMO " "
*FILE_OPERATOR "Administrator"
*FILE_PART_ID "MEAS_PBEA_00223"
*FILE_SAMPLE "NaBr"
*FILE_TYPE "RAS_RAW"
*FILE_USERGROUP "System Manager"
*FILE_VERSION "1.0000000000"
*HW_ATTACHMENT_ID "ATT1031"
*HW_ATTACHMENT_NAME "6サンプルチェンジャ|ASC-6"
*HW_COUNTER_ID-0 "CUT0021"
*HW_COUNTER_ID-1 "CUT0020"
*HW_COUNTER_ID-2 "CUT0020"
*HW_COUNTER_ID-3 "CMC0021"
*HW_COUNTER_NAME-0 "SC-70|SC-70"
*HW_COUNTER_NAME-1 "None|None"
*HW_COUNTER_NAME-2 "None|None"
*HW_COUNTER_NAME-3 "検出器モノクロメータ|Detector monochromator"
*HW_COUNTER_SELECT_NAME "SC-70|SC-70"
*HW_ECP_HV "714.0000000000"
*HW_ECP_HV_UNIT "V"
*HW_GONIOMETER_ID "GON0070"
*HW_GONIOMETER_NAME "MiniFlex 300/600|MiniFlex 300/600"
*HW_GONIOMETER_RADIUS-0 "79.0"
*HW_GONIOMETER_RADIUS-1 "91.5"
*HW_GONIOMETER_RADIUS-2 "150.0"
*HW_GONIOMETER_RADIUS-3 "0"
*HW_GONIOMETER_RADIUS-4 "103.4"
*HW_GONIOMETER_RADIUS-5 "150.0"
*HW_GONIOMETER_RADIUS-6 "46.6"
*HW_GONIOMETER_RADIUS-7 "160.0"
*HW_I_OPT_ID-0 "ISL0021"
*HW_I_OPT_ID-1 "ISO0021"
*HW_I_OPT_NAME-0 "発散スリット|Divergence slit"
*HW_I_OPT_NAME-1 "入射平行スリット|Incident parallel slit"
*HW_R_ATTENUATER_AUTOMODE "0"
*HW_R_OPT_ID-0 "RSS0021"
*HW_R_OPT_ID-1 "RSO0021"
*HW_R_OPT_ID-2 "RRS0021"
*HW_R_OPT_NAME-0 "散乱スリット|Scattering slit"
*HW_R_OPT_NAME-1 "受光平行スリット|Receiving soller slit"
*HW_R_OPT_NAME-2 "受光スリット|Receiving slit"
*HW_SAMPLE_HOLDER_ID "SMP0000"
*HW_SAMPLE_HOLDER_NAME "無し|None"
*HW_XG_CURRENT_MAX "50"
*HW_XG_CURRENT_MIN "2"
*HW_XG_CURRENT_RESOLUTION "2"
*HW_XG_CURRENT_UNIT "mA"
*HW_XG_FOCUS "1mm x 10mm"
*HW_XG_FOCUS_TYPE "Normal"
*HW_XG_ID "1062"
*HW_XG_NAME "300W/600W 封入管-A|300W/600W Sealed tube-A"
*HW_XG_TARGET_ATOMIC_NUMBER "29.0000000000"
*HW_XG_TARGET_NAME "Cu"
*HW_XG_TYPE "Compact"
*HW_XG_VOLTAGE_MAX "60"
*HW_XG_VOLTAGE_MIN "20"
*HW_XG_VOLTAGE_RESOLUTION "2"
*HW_XG_VOLTAGE_UNIT "kV"
*HW_XG_WATT_MAX "2.000"
*HW_XG_WATT_UNIT "kW"
*HW_XG_WAVE_LENGTH_ALPHA1 "1.540593"
*HW_XG_WAVE_LENGTH_ALPHA2 "1.544414"
*HW_XG_WAVE_LENGTH_BETA "1.392250"
*MEAS_COND_AXIS_NAME-0 "Theta/2-Theta"
*MEAS_COND_AXIS_NAME-1 "Spin"
*MEAS_COND_AXIS_NAME-2 "Change"
*MEAS_COND_AXIS_NAME-3 "Soller(inc.)"
*MEAS_COND_AXIS_NAME-4 "IHS"
*MEAS_COND_AXIS_NAME-5 "DS"
*MEAS_COND_AXIS_NAME-6 "SS"
*MEAS_COND_AXIS_NAME-7 "Soller(rec.)"
*MEAS_COND_AXIS_NAME-8 "RS"
*MEAS_COND_AXIS_NAME-9 "Filter"
*MEAS_COND_AXIS_NAME-10 "Monochromator"
*MEAS_COND_AXIS_NAME-11 "HV"
*MEAS_COND_AXIS_NAME-12 "PHA"
*MEAS_COND_AXIS_NAME_INTERNAL-0 "TwoThetaTheta"
*MEAS_COND_AXIS_NAME_INTERNAL-1 "Spin"
*MEAS_COND_AXIS_NAME_INTERNAL-2 "Change"
*MEAS_COND_AXIS_NAME_INTERNAL-3 "IncidentSollerSlit"
*MEAS_COND_AXIS_NAME_INTERNAL-4 "IncidentAxdSlit"
*MEAS_COND_AXIS_NAME_INTERNAL-5 "IncidentSlitBox"
*MEAS_COND_AXIS_NAME_INTERNAL-6 "ReceivingSlitBox1"
*MEAS_COND_AXIS_NAME_INTERNAL-7 "ReceivingSollerSlit"
*MEAS_COND_AXIS_NAME_INTERNAL-8 "ReceivingSlitBox2"
*MEAS_COND_AXIS_NAME_INTERNAL-9 "Filter"
*MEAS_COND_AXIS_NAME_INTERNAL-10 "CounterMonochromator"
*MEAS_COND_AXIS_NAME_INTERNAL-11 "HV"
*MEAS_COND_AXIS_NAME_INTERNAL-12 "PHA"
*MEAS_COND_AXIS_NAME_MAGICNO-0 "268632064.0000000000"
*MEAS_COND_AXIS_NAME_MAGICNO-1 "16842752.0000000000"
*MEAS_COND_AXIS_NAME_MAGICNO-2 "16842752.0000000000"
*MEAS_COND_AXIS_NAME_MAGICNO-3 "20971521.0000000000"
*MEAS_COND_AXIS_NAME_MAGICNO-4 "22020097.0000000000"
*MEAS_COND_AXIS_NAME_MAGICNO-5 "22020097.0000000000"
*MEAS_COND_AXIS_NAME_MAGICNO-6 "23068673.0000000000"
*MEAS_COND_AXIS_NAME_MAGICNO-7 "20971521.0000000000"
*MEAS_COND_AXIS_NAME_MAGICNO-8 "23068673.0000000000"
*MEAS_COND_AXIS_NAME_MAGICNO-9 "20971521.0000000000"
*MEAS_COND_AXIS_NAME_MAGICNO-10 "20971521.0000000000"
*MEAS_COND_AXIS_NAME_MAGICNO-11 "0.0000000000"
*MEAS_COND_AXIS_NAME_MAGICNO-12 "0.0000000000"
*MEAS_COND_AXIS_OFFSET-0 "0.0000000000"
*MEAS_COND_AXIS_OFFSET-1 "-"
*MEAS_COND_AXIS_OFFSET-2 "-"
*MEAS_COND_AXIS_OFFSET-3 "-"
*MEAS_COND_AXIS_OFFSET-4 "-"
*MEAS_COND_AXIS_OFFSET-5 "-"
*MEAS_COND_AXIS_OFFSET-6 "-"
*MEAS_COND_AXIS_OFFSET-7 "-"
*MEAS_COND_AXIS_OFFSET-8 "-"
*MEAS_COND_AXIS_OFFSET-9 "-"
*MEAS_COND_AXIS_OFFSET-10 "-"
*MEAS_COND_AXIS_OFFSET-11 "-"
*MEAS_COND_AXIS_OFFSET-12 "-"
*MEAS_COND_AXIS_POSITION-0 "70.0000000000"
*MEAS_COND_AXIS_POSITION-1 "0.0000000000"
*MEAS_COND_AXIS_POSITION-2 "4.0000000000"
*MEAS_COND_AXIS_POSITION-3 "2.5deg"
*MEAS_COND_AXIS_POSITION-4 "10.0mm"
*MEAS_COND_AXIS_POSITION-5 "1.250deg"
*MEAS_COND_AXIS_POSITION-6 "13.0mm(Open)"
*MEAS_COND_AXIS_POSITION-7 "5.0deg"
*MEAS_COND_AXIS_POSITION-8 "13.0mm"
*MEAS_COND_AXIS_POSITION-9 "None"
*MEAS_COND_AXIS_POSITION-10 "None"
*MEAS_COND_AXIS_POSITION-11 "714.0000000000"
*MEAS_COND_AXIS_POSITION-12 "568.7500000000"
*MEAS_COND_AXIS_UNIT-0 "deg"
*MEAS_COND_AXIS_UNIT-1 ""
*MEAS_COND_AXIS_UNIT-2 ""
*MEAS_COND_AXIS_UNIT-3 ""
*MEAS_COND_AXIS_UNIT-4 ""
*MEAS_COND_AXIS_UNIT-5 ""
*MEAS_COND_AXIS_UNIT-6 ""
*MEAS_COND_AXIS_UNIT-7 ""
*MEAS_COND_AXIS_UNIT-8 ""
*MEAS_COND_AXIS_UNIT-9 ""
*MEAS_COND_AXIS_UNIT-10 ""
*MEAS_COND_AXIS_UNIT-11 "V"
*MEAS_COND_AXIS_UNIT-12 "mV"
*MEAS_COND_CORRECTION_SLIT_COUNTERMONO "None"
*MEAS_COND_CORRECTION_SLIT_DS "1.250deg"
*MEAS_COND_CORRECTION_SLIT_FILTER "None"
*MEAS_COND_CORRECTION_SLIT_IHS "10.0mm"
*MEAS_COND_CORRECTION_SLIT_RS "13.0mm"
*MEAS_COND_CORRECTION_SLIT_SOLLER_INC "2.5deg"
*MEAS_COND_CORRECTION_SLIT_SOLLER_REC "5.0deg"
*MEAS_COND_CORRECTION_SLIT_SS "13.0mm"
*MEAS_COND_COUNTER_CNTLOSS_CORR "0.0000000000"
*MEAS_COND_COUNTER_PHABASE "568.7500000000"
*MEAS_COND_COUNTER_PHAWINDOW "926.2500000000"
*MEAS_COND_COUNTER_PHA_UNIT "mV"
*MEAS_COND_COUNTER_TAUDIFF "0.2500000000"
*MEAS_COND_COUNTER_TAUINT "0.7500000000"
*MEAS_COND_IRRADIATION_MODE "OFF"
*MEAS_COND_IRRADIATION_WIDTH ""
*MEAS_COND_OPT_ATTR " "
*MEAS_COND_OPT_NAME ""
*MEAS_COND_UNSYMMETRIC_MODE "OFF"
*MEAS_COND_XG_CURRENT "15.0000000000"
*MEAS_COND_XG_VOLTAGE "40.0000000000"
*MEAS_COND_XG_WAVE_TYPE "Ka"
*MEAS_DATA_COUNT "3400.0000000000"
*MEAS_SCAN_AXIS_X "Theta/2-Theta"
*MEAS_SCAN_AXIS_X_INTERNAL "TwoThetaTheta"
*MEAS_SCAN_END_TIME "02/21/25 12:16:26"
*MEAS_SCAN_MODE "CONTINUOUS"
*MEAS_SCAN_MONITOR "0"
*MEAS_SCAN_RESOLUTION_X "0.0025"
*MEAS_SCAN_SPEED "2.0000"
*MEAS_SCAN_SPEED_UNIT "deg/min"
*MEAS_SCAN_SPEED_USER "2.0000"
*MEAS_SCAN_START "2.0100000000"
*MEAS_SCAN_START_TIME "02/21/25 11:42:10"
*MEAS_SCAN_STEP "0.0200000000"
*MEAS_SCAN_STOP "69.9900000000"
*MEAS_SCAN_UNIT_X "deg"
*MEAS_SCAN_UNIT_Y "counts"
*SLIT_SYSTEM "0"
*RAS_HEADER_END
*RAS_INT_START
2.0100 697.0000 1.0000
2.0700 523.0000 1.0000
2.1300 710.0000 1.0000
2.1900 665.0000 1.0000
2.2500 564.0000 1.0000
2.3100 614.0000 1.0000
2.3700 630.0000 1.0000
2.4300 599.0000 1.0000
2.4900 540.0000 1.0000
2.5500 527.0000 1.0000
2.6100 551.0000 1.0000
2.6700 573.0000 1.0000
2.7300 424.0000 1.0000
2.7900 535.0000 1.0000
2.8500 472.0000 1.0000
2.9100 436.0000 1.0000
2.9700 314.0000 1.0000
3.0300 431.0000 1.0000
3.0900 411.0000 1.0000
3.1500 296.0000 1.0000
3.2100 378.0000 1.0000
3.2700 320.0000 1.0000
3.3300 292.0000 1.0000
3.3900 259.0000 1.0000
3.4500 400.0000 1.0000
3.5100 218.0000 1.0000
3.5700 366.0000 1.0000
3.6300 288.0000 1.0000
3.6900 314.0000 1.0000
3.7500 224.0000 1.0000
3.8100 274.0000 1.0000
3.8700 236.0000 1.0000
3.9300 276.0000 1.0000
3.9900 271.0000 1.0000
4.0500 254.0000 1.0000
4.1100 191.0000 1.0000
4.1700 273.0000 1.0000
4.2300 252.0000 1.0000
4.2900 196.0000 1.0000
4.3500 193.0000 1.0000
4.4100 220.0000 1.0000
4.4700 209.0000 1.0000
4.5300 185.0000 1.0000
4.5900 285.0000 1.0000
4.6500 229.0000 1.0000
4.7100 186.0000 1.0000
4.7700 188.0000 1.0000
4.8300 178.0000 1.0000
4.8900 271.0000 1.0000
4.9500 207.0000 1.0000
5.0100 239.0000 1.0000
5.0700 192.0000 1.0000
5.1300 193.0000 1.0000
5.1900 194.0000 1.0000
5.2500 238.0000 1.0000
5.3100 144.0000 1.0000
5.3700 219.0000 1.0000
5.4300 182.0000 1.0000
5.4900 194.0000 1.0000
5.5500 178.0000 1.0000
5.6100 190.0000 1.0000
5.6700 175.0000 1.0000
5.7300 215.0000 1.0000
5.7900 213.0000 1.0000
5.8500 182.0000 1.0000
5.9100 177.0000 1.0000
5.9700 191.0000 1.0000
6.0300 173.0000 1.0000
6.0900 153.0000 1.0000
6.1500 200.0000 1.0000
6.2100 208.0000 1.0000
6.2700 170.0000 1.0000
6.3300 159.0000 1.0000
6.3900 199.0000 1.0000
6.4500 208.0000 1.0000
6.5100 169.0000 1.0000
6.5700 199.0000 1.0000
6.6300 192.0000 1.0000
6.6900 170.0000 1.0000
6.7500 172.0000 1.0000
6.8100 208.0000 1.0000
6.8700 201.0000 1.0000
6.9300 213.0000 1.0000
6.9900 182.0000 1.0000
7.0500 228.0000 1.0000
7.1100 160.0000 1.0000
7.1700 180.0000 1.0000
7.2300 124.0000 1.0000
7.2900 156.0000 1.0000
7.3500 170.0000 1.0000
7.4100 146.0000 1.0000
7.4700 150.0000 1.0000
7.5300 156.0000 1.0000
7.5900 190.0000 1.0000
7.6500 144.0000 1.0000
7.7100 189.0000 1.0000
7.7700 147.0000 1.0000
7.8300 181.0000 1.0000
7.8900 147.0000 1.0000
7.9500 174.0000 1.0000
8.0100 147.0000 1.0000
8.0700 157.0000 1.0000
8.1300 140.0000 1.0000
8.1900 135.0000 1.0000
8.2500 120.0000 1.0000
8.3100 164.0000 1.0000
8.3700 136.0000 1.0000
8.4300 111.0000 1.0000
8.4900 130.0000 1.0000
8.5500 140.0000 1.0000
8.6100 119.0000 1.0000
8.6700 149.0000 1.0000
8.7300 148.0000 1.0000
8.7900 159.0000 1.0000
8.8500 154.0000 1.0000
8.9100 128.0000 1.0000
8.9700 133.0000 1.0000
9.0300 153.0000 1.0000
9.0900 105.0000 1.0000
9.1500 145.0000 1.0000
9.2100 93.0000 1.0000
9.2700 145.0000 1.0000
9.3300 100.0000 1.0000
9.3900 109.0000 1.0000
9.4500 134.0000 1.0000
9.5100 126.0000 1.0000
9.5700 109.0000 1.0000
9.6300 132.0000 1.0000
9.6900 120.0000 1.0000
9.7500 104.0000 1.0000
9.8100 124.0000 1.0000
9.8700 131.0000 1.0000
9.9300 132.0000 1.0000
9.9900 114.0000 1.0000
10.0500 115.0000 1.0000
10.1100 107.0000 1.0000
10.1700 127.0000 1.0000
10.2300 128.0000 1.0000
10.2900 105.0000 1.0000
10.3500 116.0000 1.0000
10.4100 102.0000 1.0000
10.4700 102.0000 1.0000
10.5300 117.0000 1.0000
10.5900 97.0000 1.0000
10.6500 128.0000 1.0000
10.7100 115.0000 1.0000
10.7700 104.0000 1.0000
10.8300 109.0000 1.0000
10.8900 137.0000 1.0000
10.9500 102.0000 1.0000
11.0100 105.0000 1.0000
11.0700 91.0000 1.0000
11.1300 91.0000 1.0000
11.1900 100.0000 1.0000
11.2500 105.0000 1.0000
11.3100 84.0000 1.0000
11.3700 113.0000 1.0000
11.4300 80.0000 1.0000
11.4900 93.0000 1.0000
11.5500 83.0000 1.0000
11.6100 89.0000 1.0000
11.6700 90.0000 1.0000
11.7300 92.0000 1.0000
11.7900 87.0000 1.0000
11.8500 114.0000 1.0000
11.9100 94.0000 1.0000
11.9700 94.0000 1.0000
12.0300 96.0000 1.0000
12.0900 96.0000 1.0000
12.1500 100.0000 1.0000
12.2100 83.0000 1.0000
12.2700 78.0000 1.0000
12.3300 74.0000 1.0000
12.3900 74.0000 1.0000
12.4500 78.0000 1.0000
12.5100 93.0000 1.0000
12.5700 77.0000 1.0000
12.6300 86.0000 1.0000
12.6900 88.0000 1.0000
12.7500 97.0000 1.0000
12.8100 104.0000 1.0000
12.8700 78.0000 1.0000
12.9300 88.0000 1.0000
12.9900 79.0000 1.0000
13.0500 93.0000 1.0000
13.1100 66.0000 1.0000
13.1700 85.0000 1.0000
13.2300 81.0000 1.0000
13.2900 69.0000 1.0000
13.3500 71.0000 1.0000
13.4100 74.0000 1.0000
13.4700 63.0000 1.0000
13.5300 79.0000 1.0000
13.5900 84.0000 1.0000
13.6500 97.0000 1.0000
13.7100 91.0000 1.0000
13.7700 79.0000 1.0000
13.8300 91.0000 1.0000
13.8900 92.0000 1.0000
13.9500 66.0000 1.0000
14.0100 75.0000 1.0000
14.0700 85.0000 1.0000
14.1300 89.0000 1.0000
14.1900 84.0000 1.0000
14.2500 80.0000 1.0000
14.3100 81.0000 1.0000
14.3700 74.0000 1.0000
14.4300 84.0000 1.0000
14.4900 63.0000 1.0000
14.5500 93.0000 1.0000
14.6100 70.0000 1.0000
14.6700 83.0000 1.0000
14.7300 104.0000 1.0000
14.7900 72.0000 1.0000
14.8500 91.0000 1.0000
14.9100 82.0000 1.0000
14.9700 74.0000 1.0000
15.0300 64.0000 1.0000
15.0900 74.0000 1.0000
15.1500 63.0000 1.0000
15.2100 85.0000 1.0000
15.2700 66.0000 1.0000
15.3300 72.0000 1.0000
15.3900 75.0000 1.0000
15.4500 64.0000 1.0000
15.5100 57.0000 1.0000
15.5700 59.0000 1.0000
15.6300 60.0000 1.0000
15.6900 64.0000 1.0000
15.7500 76.0000 1.0000
15.8100 66.0000 1.0000
15.8700 78.0000 1.0000
15.9300 69.0000 1.0000
15.9900 71.0000 1.0000
16.0500 69.0000 1.0000
16.1100 79.0000 1.0000
16.1700 59.0000 1.0000
16.2300 61.0000 1.0000
16.2900 76.0000 1.0000
16.3500 71.0000 1.0000
16.4100 67.0000 1.0000
16.4700 63.0000 1.0000
16.5300 95.0000 1.0000
16.5900 75.0000 1.0000
16.6500 71.0000 1.0000
16.7100 67.0000 1.0000
16.7700 95.0000 1.0000
16.8300 80.0000 1.0000
16.8900 114.0000 1.0000
16.9500 217.0000 1.0000
17.0100 448.0000 1.0000
17.0700 394.0000 1.0000
17.1300 160.0000 1.0000
17.1900 93.0000 1.0000
17.2500 73.0000 1.0000
17.3100 75.0000 1.0000
17.3700 63.0000 1.0000
17.4300 74.0000 1.0000
17.4900 64.0000 1.0000
17.5500 79.0000 1.0000
17.6100 72.0000 1.0000
17.6700 57.0000 1.0000
17.7300 70.0000 1.0000
17.7900 56.0000 1.0000
17.8500 56.0000 1.0000
17.9100 81.0000 1.0000
17.9700 82.0000 1.0000
18.0300 79.0000 1.0000
18.0900 85.0000 1.0000
18.1500 68.0000 1.0000
18.2100 79.0000 1.0000
18.2700 59.0000 1.0000
18.3300 71.0000 1.0000
18.3900 67.0000 1.0000
18.4500 58.0000 1.0000
18.5100 49.0000 1.0000
18.5700 57.0000 1.0000
18.6300 69.0000 1.0000
18.6900 67.0000 1.0000
18.7500 51.0000 1.0000
18.8100 53.0000 1.0000
18.8700 64.0000 1.0000
18.9300 62.0000 1.0000
18.9900 64.0000 1.0000
19.0500 61.0000 1.0000
19.1100 54.0000 1.0000
19.1700 61.0000 1.0000
19.2300 53.0000 1.0000
19.2900 63.0000 1.0000
19.3500 50.0000 1.0000
19.4100 57.0000 1.0000
19.4700 58.0000 1.0000
19.5300 59.0000 1.0000
19.5900 61.0000 1.0000
19.6500 64.0000 1.0000
19.7100 68.0000 1.0000
19.7700 62.0000 1.0000
19.8300 75.0000 1.0000
19.8900 53.0000 1.0000
19.9500 54.0000 1.0000
20.0100 65.0000 1.0000
20.0700 65.0000 1.0000
20.1300 67.0000 1.0000
20.1900 52.0000 1.0000
20.2500 66.0000 1.0000
20.3100 50.0000 1.0000
20.3700 64.0000 1.0000
20.4300 53.0000 1.0000
20.4900 49.0000 1.0000
20.5500 59.0000 1.0000
20.6100 54.0000 1.0000
20.6700 59.0000 1.0000
20.7300 58.0000 1.0000
20.7900 63.0000 1.0000
20.8500 51.0000 1.0000
20.9100 67.0000 1.0000
20.9700 49.0000 1.0000
21.0300 58.0000 1.0000
21.0900 50.0000 1.0000
21.1500 56.0000 1.0000
21.2100 60.0000 1.0000
21.2700 56.0000 1.0000
21.3300 61.0000 1.0000
21.3900 53.0000 1.0000
21.4500 58.0000 1.0000
21.5100 70.0000 1.0000
21.5700 65.0000 1.0000
21.6300 58.0000 1.0000
21.6900 45.0000 1.0000
21.7500 76.0000 1.0000
21.8100 52.0000 1.0000
21.8700 55.0000 1.0000
21.9300 66.0000 1.0000
21.9900 68.0000 1.0000
22.0500 76.0000 1.0000
22.1100 63.0000 1.0000
22.1700 97.0000 1.0000
22.2300 348.0000 1.0000
22.2900 641.0000 1.0000
22.3500 263.0000 1.0000
22.4100 96.0000 1.0000
22.4700 68.0000 1.0000
22.5300 69.0000 1.0000
22.5900 82.0000 1.0000
22.6500 78.0000 1.0000
22.7100 67.0000 1.0000
22.7700 60.0000 1.0000
22.8300 58.0000 1.0000
22.8900 58.0000 1.0000
22.9500 63.0000 1.0000
23.0100 55.0000 1.0000
23.0700 71.0000 1.0000
23.1300 55.0000 1.0000
23.1900 60.0000 1.0000
23.2500 77.0000 1.0000
23.3100 177.0000 1.0000
23.3700 178.0000 1.0000
23.4300 115.0000 1.0000
23.4900 124.0000 1.0000
23.5500 518.0000 1.0000
23.6100 285.0000 1.0000
23.6700 86.0000 1.0000
23.7300 63.0000 1.0000
23.7900 52.0000 1.0000
23.8500 52.0000 1.0000
23.9100 73.0000 1.0000
23.9700 46.0000 1.0000
24.0300 53.0000 1.0000
24.0900 61.0000 1.0000
24.1500 53.0000 1.0000
24.2100 58.0000 1.0000
24.2700 40.0000 1.0000
24.3300 47.0000 1.0000
24.3900 58.0000 1.0000
24.4500 58.0000 1.0000
24.5100 48.0000 1.0000
24.5700 52.0000 1.0000
24.6300 54.0000 1.0000
24.6900 60.0000 1.0000
24.7500 60.0000 1.0000
24.8100 55.0000 1.0000
24.8700 47.0000 1.0000
24.9300 62.0000 1.0000
24.9900 47.0000 1.0000
25.0500 56.0000 1.0000
25.1100 49.0000 1.0000
25.1700 55.0000 1.0000
25.2300 52.0000 1.0000
25.2900 51.0000 1.0000
25.3500 53.0000 1.0000
25.4100 66.0000 1.0000
25.4700 70.0000 1.0000
25.5300 70.0000 1.0000
25.5900 71.0000 1.0000
25.6500 71.0000 1.0000
25.7100 65.0000 1.0000
25.7700 99.0000 1.0000
25.8300 359.0000 1.0000
25.8900 596.0000 1.0000
25.9500 473.0000 1.0000
26.0100 193.0000 1.0000
26.0700 181.0000 1.0000
26.1300 168.0000 1.0000
26.1900 114.0000 1.0000
26.2500 60.0000 1.0000
26.3100 63.0000 1.0000
26.3700 75.0000 1.0000
26.4300 62.0000 1.0000
26.4900 82.0000 1.0000
26.5500 133.0000 1.0000
26.6100 186.0000 1.0000
26.6700 148.0000 1.0000
26.7300 107.0000 1.0000
26.7900 65.0000 1.0000
26.8500 57.0000 1.0000
26.9100 69.0000 1.0000
26.9700 65.0000 1.0000
27.0300 75.0000 1.0000
27.0900 73.0000 1.0000
27.1500 57.0000 1.0000
27.2100 73.0000 1.0000
27.2700 69.0000 1.0000
27.3300 75.0000 1.0000
27.3900 50.0000 1.0000
27.4500 64.0000 1.0000
27.5100 51.0000 1.0000
27.5700 57.0000 1.0000
27.6300 55.0000 1.0000
27.6900 52.0000 1.0000
27.7500 53.0000 1.0000
27.8100 69.0000 1.0000
27.8700 75.0000 1.0000
27.9300 78.0000 1.0000
27.9900 55.0000 1.0000
28.0500 82.0000 1.0000
28.1100 64.0000 1.0000
28.1700 60.0000 1.0000
28.2300 67.0000 1.0000
28.2900 55.0000 1.0000
28.3500 73.0000 1.0000
28.4100 77.0000 1.0000
28.4700 66.0000 1.0000
28.5300 93.0000 1.0000
28.5900 116.0000 1.0000
28.6500 136.0000 1.0000
28.7100 193.0000 1.0000
28.7700 1202.0000 1.0000
28.8300 1485.0000 1.0000
28.8900 796.0000 1.0000
28.9500 128.0000 1.0000
29.0100 96.0000 1.0000
29.0700 92.0000 1.0000
29.1300 65.0000 1.0000
29.1900 81.0000 1.0000
29.2500 69.0000 1.0000
29.3100 72.0000 1.0000
29.3700 78.0000 1.0000
29.4300 72.0000 1.0000
29.4900 79.0000 1.0000
29.5500 148.0000 1.0000
29.6100 286.0000 1.0000
29.6700 471.0000 1.0000
29.7300 942.0000 1.0000
29.7900 968.0000 1.0000
29.8500 466.0000 1.0000
29.9100 136.0000 1.0000
29.9700 96.0000 1.0000
30.0300 94.0000 1.0000
30.0900 76.0000 1.0000
30.1500 72.0000 1.0000
30.2100 107.0000 1.0000
30.2700 162.0000 1.0000
30.3300 154.0000 1.0000
30.3900 94.0000 1.0000
30.4500 69.0000 1.0000
30.5100 156.0000 1.0000
30.5700 125.0000 1.0000
30.6300 93.0000 1.0000
30.6900 87.0000 1.0000
30.7500 71.0000 1.0000
30.8100 65.0000 1.0000
30.8700 57.0000 1.0000
30.9300 59.0000 1.0000
30.9900 49.0000 1.0000
31.0500 76.0000 1.0000
31.1100 86.0000 1.0000
31.1700 102.0000 1.0000
31.2300 77.0000 1.0000
31.2900 69.0000 1.0000
31.3500 57.0000 1.0000
31.4100 51.0000 1.0000
31.4700 46.0000 1.0000
31.5300 67.0000 1.0000
31.5900 70.0000 1.0000
31.6500 68.0000 1.0000
31.7100 67.0000 1.0000
31.7700 60.0000 1.0000
31.8300 63.0000 1.0000
31.8900 61.0000 1.0000
31.9500 67.0000 1.0000
32.0100 74.0000 1.0000
32.0700 109.0000 1.0000
32.1300 103.0000 1.0000
32.1900 80.0000 1.0000
32.2500 83.0000 1.0000
32.3100 153.0000 1.0000
32.3700 195.0000 1.0000
32.4300 129.0000 1.0000
32.4900 69.0000 1.0000
32.5500 59.0000 1.0000
32.6100 71.0000 1.0000
32.6700 63.0000 1.0000
32.7300 71.0000 1.0000
32.7900 54.0000 1.0000
32.8500 57.0000 1.0000
32.9100 66.0000 1.0000
32.9700 60.0000 1.0000
33.0300 62.0000 1.0000
33.0900 58.0000 1.0000
33.1500 77.0000 1.0000
33.2100 77.0000 1.0000
33.2700 85.0000 1.0000
33.3300 164.0000 1.0000
33.3900 290.0000 1.0000
33.4500 220.0000 1.0000
33.5100 127.0000 1.0000
33.5700 80.0000 1.0000
33.6300 98.0000 1.0000
33.6900 67.0000 1.0000
33.7500 73.0000 1.0000
33.8100 78.0000 1.0000
33.8700 65.0000 1.0000
33.9300 58.0000 1.0000
33.9900 58.0000 1.0000
34.0500 69.0000 1.0000
34.1100 60.0000 1.0000
34.1700 65.0000 1.0000
34.2300 66.0000 1.0000
34.2900 127.0000 1.0000
34.3500 419.0000 1.0000
34.4100 499.0000 1.0000
34.4700 310.0000 1.0000
34.5300 113.0000 1.0000
34.5900 70.0000 1.0000
34.6500 59.0000 1.0000
34.7100 59.0000 1.0000
34.7700 66.0000 1.0000
34.8300 63.0000 1.0000
34.8900 62.0000 1.0000
34.9500 55.0000 1.0000
35.0100 51.0000 1.0000
35.0700 64.0000 1.0000
35.1300 62.0000 1.0000
35.1900 55.0000 1.0000
35.2500 53.0000 1.0000
35.3100 72.0000 1.0000
35.3700 57.0000 1.0000
35.4300 61.0000 1.0000
35.4900 59.0000 1.0000
35.5500 72.0000 1.0000
35.6100 85.0000 1.0000
35.6700 241.0000 1.0000
35.7300 324.0000 1.0000
35.7900 192.0000 1.0000
35.8500 95.0000 1.0000
35.9100 62.0000 1.0000
35.9700 45.0000 1.0000
36.0300 81.0000 1.0000
36.0900 71.0000 1.0000
36.1500 49.0000 1.0000
36.2100 56.0000 1.0000
36.2700 59.0000 1.0000
36.3300 57.0000 1.0000
36.3900 51.0000 1.0000
36.4500 63.0000 1.0000
36.5100 49.0000 1.0000
36.5700 59.0000 1.0000
36.6300 52.0000 1.0000
36.6900 58.0000 1.0000
36.7500 56.0000 1.0000
36.8100 49.0000 1.0000
36.8700 56.0000 1.0000
36.9300 62.0000 1.0000
36.9900 55.0000 1.0000
37.0500 61.0000 1.0000
37.1100 62.0000 1.0000
37.1700 87.0000 1.0000
37.2300 77.0000 1.0000
37.2900 99.0000 1.0000
37.3500 88.0000 1.0000
37.4100 390.0000 1.0000
37.4700 688.0000 1.0000
37.5300 538.0000 1.0000
37.5900 312.0000 1.0000
37.6500 126.0000 1.0000
37.7100 76.0000 1.0000
37.7700 64.0000 1.0000
37.8300 58.0000 1.0000
37.8900 60.0000 1.0000
37.9500 66.0000 1.0000
38.0100 54.0000 1.0000
38.0700 54.0000 1.0000
38.1300 65.0000 1.0000
38.1900 54.0000 1.0000
38.2500 49.0000 1.0000
38.3100 62.0000 1.0000
38.3700 52.0000 1.0000
38.4300 69.0000 1.0000
38.4900 62.0000 1.0000
38.5500 63.0000 1.0000
38.6100 79.0000 1.0000
38.6700 52.0000 1.0000
38.7300 58.0000 1.0000
38.7900 56.0000 1.0000
38.8500 58.0000 1.0000
38.9100 47.0000 1.0000
38.9700 54.0000 1.0000
39.0300 54.0000 1.0000
39.0900 65.0000 1.0000
39.1500 64.0000 1.0000
39.2100 60.0000 1.0000
39.2700 61.0000 1.0000
39.3300 59.0000 1.0000
39.3900 57.0000 1.0000
39.4500 78.0000 1.0000
39.5100 52.0000 1.0000
39.5700 68.0000 1.0000
39.6300 58.0000 1.0000
39.6900 59.0000 1.0000
39.7500 59.0000 1.0000
39.8100 58.0000 1.0000
39.8700 64.0000 1.0000
39.9300 55.0000 1.0000
39.9900 49.0000 1.0000
40.0500 62.0000 1.0000
40.1100 53.0000 1.0000
40.1700 60.0000 1.0000
40.2300 65.0000 1.0000
40.2900 46.0000 1.0000
40.3500 66.0000 1.0000
40.4100 64.0000 1.0000
40.4700 59.0000 1.0000
40.5300 51.0000 1.0000
40.5900 51.0000 1.0000
40.6500 54.0000 1.0000
40.7100 43.0000 1.0000
40.7700 57.0000 1.0000
40.8300 61.0000 1.0000
40.8900 52.0000 1.0000
40.9500 40.0000 1.0000
41.0100 61.0000 1.0000
41.0700 120.0000 1.0000
41.1300 102.0000 1.0000
41.1900 113.0000 1.0000
41.2500 83.0000 1.0000
41.3100 67.0000 1.0000
41.3700 59.0000 1.0000
41.4300 75.0000 1.0000
41.4900 81.0000 1.0000
41.5500 166.0000 1.0000
41.6100 216.0000 1.0000
41.6700 161.0000 1.0000
41.7300 118.0000 1.0000
41.7900 82.0000 1.0000
41.8500 65.0000 1.0000
41.9100 63.0000 1.0000
41.9700 57.0000 1.0000
42.0300 49.0000 1.0000
42.0900 52.0000 1.0000
42.1500 62.0000 1.0000
42.2100 59.0000 1.0000
42.2700 67.0000 1.0000
42.3300 56.0000 1.0000
42.3900 48.0000 1.0000
42.4500 63.0000 1.0000
42.5100 57.0000 1.0000
42.5700 62.0000 1.0000
42.6300 56.0000 1.0000
42.6900 60.0000 1.0000
42.7500 76.0000 1.0000
42.8100 74.0000 1.0000
42.8700 76.0000 1.0000
42.9300 62.0000 1.0000
42.9900 78.0000 1.0000
43.0500 72.0000 1.0000
43.1100 58.0000 1.0000
43.1700 55.0000 1.0000
43.2300 56.0000 1.0000
43.2900 73.0000 1.0000
43.3500 80.0000 1.0000
43.4100 52.0000 1.0000
43.4700 60.0000 1.0000
43.5300 55.0000 1.0000
43.5900 74.0000 1.0000
43.6500 65.0000 1.0000
43.7100 63.0000 1.0000
43.7700 64.0000 1.0000
43.8300 66.0000 1.0000
43.8900 66.0000 1.0000
43.9500 89.0000 1.0000
44.0100 75.0000 1.0000
44.0700 86.0000 1.0000
44.1300 68.0000 1.0000
44.1900 66.0000 1.0000
44.2500 64.0000 1.0000
44.3100 54.0000 1.0000
44.3700 74.0000 1.0000
44.4300 78.0000 1.0000
44.4900 86.0000 1.0000
44.5500 80.0000 1.0000
44.6100 90.0000 1.0000
44.6700 106.0000 1.0000
44.7300 86.0000 1.0000
44.7900 106.0000 1.0000
44.8500 133.0000 1.0000
44.9100 935.0000 1.0000
44.9700 657.0000 1.0000
45.0300 559.0000 1.0000
45.0900 309.0000 1.0000
45.1500 126.0000 1.0000
45.2100 94.0000 1.0000
45.2700 63.0000 1.0000
45.3300 60.0000 1.0000
45.3900 67.0000 1.0000
45.4500 70.0000 1.0000
45.5100 72.0000 1.0000
45.5700 63.0000 1.0000
45.6300 54.0000 1.0000
45.6900 69.0000 1.0000
45.7500 78.0000 1.0000
45.8100 74.0000 1.0000
45.8700 81.0000 1.0000
45.9300 70.0000 1.0000
45.9900 109.0000 1.0000
46.0500 108.0000 1.0000
46.1100 75.0000 1.0000
46.1700 87.0000 1.0000
46.2300 65.0000 1.0000
46.2900 80.0000 1.0000
46.3500 74.0000 1.0000
46.4100 105.0000 1.0000
46.4700 61.0000 1.0000
46.5300 87.0000 1.0000
46.5900 58.0000 1.0000
46.6500 74.0000 1.0000
46.7100 57.0000 1.0000
46.7700 52.0000 1.0000
46.8300 58.0000 1.0000
46.8900 56.0000 1.0000
46.9500 58.0000 1.0000
47.0100 46.0000 1.0000
47.0700 58.0000 1.0000
47.1300 56.0000 1.0000
47.1900 53.0000 1.0000
47.2500 58.0000 1.0000
47.3100 58.0000 1.0000
47.3700 59.0000 1.0000
47.4300 43.0000 1.0000
47.4900 64.0000 1.0000
47.5500 56.0000 1.0000
47.6100 84.0000 1.0000
47.6700 39.0000 1.0000
47.7300 57.0000 1.0000
47.7900 60.0000 1.0000
47.8500 54.0000 1.0000
47.9100 53.0000 1.0000
47.9700 55.0000 1.0000
48.0300 67.0000 1.0000
48.0900 44.0000 1.0000
48.1500 47.0000 1.0000
48.2100 58.0000 1.0000
48.2700 55.0000 1.0000
48.3300 59.0000 1.0000
48.3900 58.0000 1.0000
48.4500 47.0000 1.0000
48.5100 66.0000 1.0000
48.5700 62.0000 1.0000
48.6300 58.0000 1.0000
48.6900 54.0000 1.0000
48.7500 66.0000 1.0000
48.8100 48.0000 1.0000
48.8700 65.0000 1.0000
48.9300 55.0000 1.0000
48.9900 67.0000 1.0000
49.0500 88.0000 1.0000
49.1100 289.0000 1.0000
49.1700 94.0000 1.0000
49.2300 144.0000 1.0000
49.2900 87.0000 1.0000
49.3500 51.0000 1.0000
49.4100 62.0000 1.0000
49.4700 53.0000 1.0000
49.5300 49.0000 1.0000
49.5900 60.0000 1.0000
49.6500 43.0000 1.0000
49.7100 56.0000 1.0000
49.7700 50.0000 1.0000
49.8300 65.0000 1.0000
49.8900 63.0000 1.0000
49.9500 55.0000 1.0000
50.0100 56.0000 1.0000
50.0700 58.0000 1.0000
50.1300 58.0000 1.0000
50.1900 55.0000 1.0000
50.2500 64.0000 1.0000
50.3100 54.0000 1.0000
50.3700 65.0000 1.0000
50.4300 61.0000 1.0000
50.4900 52.0000 1.0000
50.5500 59.0000 1.0000
50.6100 51.0000 1.0000
50.6700 79.0000 1.0000
50.7300 57.0000 1.0000
50.7900 62.0000 1.0000
50.8500 65.0000 1.0000
50.9100 53.0000 1.0000
50.9700 51.0000 1.0000
51.0300 75.0000 1.0000
51.0900 59.0000 1.0000
51.1500 61.0000 1.0000
51.2100 51.0000 1.0000
51.2700 53.0000 1.0000
51.3300 53.0000 1.0000
51.3900 64.0000 1.0000
51.4500 43.0000 1.0000
51.5100 48.0000 1.0000
51.5700 52.0000 1.0000
51.6300 58.0000 1.0000
51.6900 49.0000 1.0000
51.7500 65.0000 1.0000
51.8100 52.0000 1.0000
51.8700 64.0000 1.0000
51.9300 51.0000 1.0000
51.9900 56.0000 1.0000
52.0500 61.0000 1.0000
52.1100 49.0000 1.0000
52.1700 76.0000 1.0000
52.2300 66.0000 1.0000
52.2900 53.0000 1.0000
52.3500 77.0000 1.0000
52.4100 60.0000 1.0000
52.4700 69.0000 1.0000
52.5300 52.0000 1.0000
52.5900 47.0000 1.0000
52.6500 53.0000 1.0000
52.7100 50.0000 1.0000
52.7700 69.0000 1.0000
52.8300 52.0000 1.0000
52.8900 63.0000 1.0000
52.9500 65.0000 1.0000
53.0100 49.0000 1.0000
53.0700 65.0000 1.0000
53.1300 45.0000 1.0000
53.1900 56.0000 1.0000
53.2500 56.0000 1.0000
53.3100 51.0000 1.0000
53.3700 76.0000 1.0000
53.4300 58.0000 1.0000
53.4900 49.0000 1.0000
53.5500 46.0000 1.0000
53.6100 55.0000 1.0000
53.6700 43.0000 1.0000
53.7300 47.0000 1.0000
53.7900 46.0000 1.0000
53.8500 50.0000 1.0000
53.9100 46.0000 1.0000
53.9700 47.0000 1.0000
54.0300 51.0000 1.0000
54.0900 51.0000 1.0000
54.1500 64.0000 1.0000
54.2100 51.0000 1.0000
54.2700 51.0000 1.0000
54.3300 43.0000 1.0000
54.3900 47.0000 1.0000
54.4500 64.0000 1.0000
54.5100 50.0000 1.0000
54.5700 54.0000 1.0000
54.6300 63.0000 1.0000
54.6900 81.0000 1.0000
54.7500 82.0000 1.0000
54.8100 60.0000 1.0000
54.8700 103.0000 1.0000
54.9300 84.0000 1.0000
54.9900 67.0000 1.0000
55.0500 79.0000 1.0000
55.1100 72.0000 1.0000
55.1700 44.0000 1.0000
55.2300 62.0000 1.0000
55.2900 71.0000 1.0000
55.3500 55.0000 1.0000
55.4100 48.0000 1.0000
55.4700 59.0000 1.0000
55.5300 46.0000 1.0000
55.5900 65.0000 1.0000
55.6500 60.0000 1.0000
55.7100 72.0000 1.0000
55.7700 66.0000 1.0000
55.8300 54.0000 1.0000
55.8900 61.0000 1.0000
55.9500 109.0000 1.0000
56.0100 84.0000 1.0000
56.0700 78.0000 1.0000
56.1300 82.0000 1.0000
56.1900 48.0000 1.0000
56.2500 45.0000 1.0000
56.3100 54.0000 1.0000
56.3700 63.0000 1.0000
56.4300 52.0000 1.0000
56.4900 66.0000 1.0000
56.5500 62.0000 1.0000
56.6100 49.0000 1.0000
56.6700 68.0000 1.0000
56.7300 58.0000 1.0000
56.7900 45.0000 1.0000
56.8500 45.0000 1.0000
56.9100 64.0000 1.0000
56.9700 61.0000 1.0000
57.0300 66.0000 1.0000
57.0900 52.0000 1.0000
57.1500 49.0000 1.0000
57.2100 53.0000 1.0000
57.2700 59.0000 1.0000
57.3300 58.0000 1.0000
57.3900 67.0000 1.0000
57.4500 61.0000 1.0000
57.5100 48.0000 1.0000
57.5700 56.0000 1.0000
57.6300 65.0000 1.0000
57.6900 68.0000 1.0000
57.7500 127.0000 1.0000
57.8100 135.0000 1.0000
57.8700 73.0000 1.0000
57.9300 118.0000 1.0000
57.9900 93.0000 1.0000
58.0500 61.0000 1.0000
58.1100 54.0000 1.0000
58.1700 57.0000 1.0000
58.2300 73.0000 1.0000
58.2900 62.0000 1.0000
58.3500 67.0000 1.0000
58.4100 53.0000 1.0000
58.4700 62.0000 1.0000
58.5300 62.0000 1.0000
58.5900 62.0000 1.0000
58.6500 58.0000 1.0000
58.7100 62.0000 1.0000
58.7700 45.0000 1.0000
58.8300 57.0000 1.0000
58.8900 43.0000 1.0000
58.9500 57.0000 1.0000
59.0100 56.0000 1.0000
59.0700 52.0000 1.0000
59.1300 57.0000 1.0000
59.1900 60.0000 1.0000
59.2500 48.0000 1.0000
59.3100 43.0000 1.0000
59.3700 49.0000 1.0000
59.4300 53.0000 1.0000
59.4900 60.0000 1.0000
59.5500 56.0000 1.0000
59.6100 55.0000 1.0000
59.6700 54.0000 1.0000
59.7300 53.0000 1.0000
59.7900 46.0000 1.0000
59.8500 59.0000 1.0000
59.9100 65.0000 1.0000
59.9700 48.0000 1.0000
60.0300 65.0000 1.0000
60.0900 61.0000 1.0000
60.1500 53.0000 1.0000
60.2100 61.0000 1.0000
60.2700 57.0000 1.0000
60.3300 61.0000 1.0000
60.3900 72.0000 1.0000
60.4500 159.0000 1.0000
60.5100 252.0000 1.0000
60.5700 190.0000 1.0000
60.6300 188.0000 1.0000
60.6900 160.0000 1.0000
60.7500 132.0000 1.0000
60.8100 56.0000 1.0000
60.8700 62.0000 1.0000
60.9300 55.0000 1.0000
60.9900 60.0000 1.0000
61.0500 52.0000 1.0000
61.1100 61.0000 1.0000
61.1700 55.0000 1.0000
61.2300 50.0000 1.0000
61.2900 63.0000 1.0000
61.3500 64.0000 1.0000
61.4100 49.0000 1.0000
61.4700 66.0000 1.0000
61.5300 54.0000 1.0000
61.5900 62.0000 1.0000
61.6500 51.0000 1.0000
61.7100 62.0000 1.0000
61.7700 56.0000 1.0000
61.8300 63.0000 1.0000
61.8900 50.0000 1.0000
61.9500 56.0000 1.0000
62.0100 60.0000 1.0000
62.0700 76.0000 1.0000
62.1300 67.0000 1.0000
62.1900 63.0000 1.0000
62.2500 67.0000 1.0000
62.3100 63.0000 1.0000
62.3700 51.0000 1.0000
62.4300 50.0000 1.0000
62.4900 48.0000 1.0000
62.5500 60.0000 1.0000
62.6100 52.0000 1.0000
62.6700 68.0000 1.0000
62.7300 60.0000 1.0000
62.7900 66.0000 1.0000
62.8500 48.0000 1.0000
62.9100 61.0000 1.0000
62.9700 61.0000 1.0000
63.0300 55.0000 1.0000
63.0900 57.0000 1.0000
63.1500 57.0000 1.0000
63.2100 62.0000 1.0000
63.2700 67.0000 1.0000
63.3300 52.0000 1.0000
63.3900 53.0000 1.0000
63.4500 53.0000 1.0000
63.5100 59.0000 1.0000
63.5700 50.0000 1.0000
63.6300 54.0000 1.0000
63.6900 56.0000 1.0000
63.7500 51.0000 1.0000
63.8100 51.0000 1.0000
63.8700 48.0000 1.0000
63.9300 46.0000 1.0000
63.9900 49.0000 1.0000
64.0500 60.0000 1.0000
64.1100 59.0000 1.0000
64.1700 54.0000 1.0000
64.2300 57.0000 1.0000
64.2900 58.0000 1.0000
64.3500 54.0000 1.0000
64.4100 49.0000 1.0000
64.4700 50.0000 1.0000
64.5300 46.0000 1.0000
64.5900 49.0000 1.0000
64.6500 52.0000 1.0000
64.7100 48.0000 1.0000
64.7700 44.0000 1.0000
64.8300 52.0000 1.0000
64.8900 45.0000 1.0000
64.9500 53.0000 1.0000
65.0100 44.0000 1.0000
65.0700 60.0000 1.0000
65.1300 59.0000 1.0000
65.1900 63.0000 1.0000
65.2500 59.0000 1.0000
65.3100 59.0000 1.0000
65.3700 66.0000 1.0000
65.4300 64.0000 1.0000
65.4900 59.0000 1.0000
65.5500 49.0000 1.0000
65.6100 59.0000 1.0000
65.6700 57.0000 1.0000
65.7300 65.0000 1.0000
65.7900 53.0000 1.0000
65.8500 41.0000 1.0000
65.9100 48.0000 1.0000
65.9700 57.0000 1.0000
66.0300 54.0000 1.0000
66.0900 55.0000 1.0000
66.1500 44.0000 1.0000
66.2100 54.0000 1.0000
66.2700 52.0000 1.0000
66.3300 51.0000 1.0000
66.3900 66.0000 1.0000
66.4500 65.0000 1.0000
66.5100 65.0000 1.0000
66.5700 57.0000 1.0000
66.6300 51.0000 1.0000
66.6900 49.0000 1.0000
66.7500 55.0000 1.0000
66.8100 52.0000 1.0000
66.8700 58.0000 1.0000
66.9300 54.0000 1.0000
66.9900 55.0000 1.0000
67.0500 60.0000 1.0000
67.1100 57.0000 1.0000
67.1700 57.0000 1.0000
67.2300 64.0000 1.0000
67.2900 55.0000 1.0000
67.3500 73.0000 1.0000
67.4100 36.0000 1.0000
67.4700 41.0000 1.0000
67.5300 53.0000 1.0000
67.5900 44.0000 1.0000
67.6500 53.0000 1.0000
67.7100 55.0000 1.0000
67.7700 51.0000 1.0000
67.8300 69.0000 1.0000
67.8900 48.0000 1.0000
67.9500 55.0000 1.0000
68.0100 47.0000 1.0000
68.0700 53.0000 1.0000
68.1300 49.0000 1.0000
68.1900 53.0000 1.0000
68.2500 61.0000 1.0000
68.3100 65.0000 1.0000
68.3700 62.0000 1.0000
68.4300 57.0000 1.0000
68.4900 68.0000 1.0000
68.5500 65.0000 1.0000
68.6100 56.0000 1.0000
68.6700 55.0000 1.0000
68.7300 58.0000 1.0000
68.7900 59.0000 1.0000
68.8500 54.0000 1.0000
68.9100 50.0000 1.0000
68.9700 53.0000 1.0000
69.0300 51.0000 1.0000
69.0900 49.0000 1.0000
69.1500 60.0000 1.0000
69.2100 67.0000 1.0000
69.2700 49.0000 1.0000
69.3300 46.0000 1.0000
69.3900 54.0000 1.0000
69.4500 58.0000 1.0000
69.5100 59.0000 1.0000
69.5700 50.0000 1.0000
69.6300 46.0000 1.0000
69.6900 51.0000 1.0000
69.7500 48.0000 1.0000
69.8100 54.0000 1.0000
69.8700 60.0000 1.0000
69.9300 64.0000 1.0000
69.9900 60.0000 1.0000
*RAS_INT_END
*RAS_DATA_END