File: XRD/NaCl.ras
*RAS_DATA_START
*RAS_HEADER_START
*DISP_FMT_X "%.2f"
*DISP_FMT_Y "%.0f"
*DISP_FULLSCALE "14370.0000000000"
*DISP_LINE_COLOR "255.0000000000"
*DISP_LINE_STYLE "0.0000000000"
*DISP_LINE_WIDTH "0.2500000000"
*DISP_NOTE "Collected Data-1"
*DISP_OFFSET_Y "0.0000000000"
*DISP_PEAKSEARCH_UNIT_Y "COUNTS"
*DISP_RANGE_BOTTOM "0.0000000000"
*DISP_RANGE_LEFT "2.0100000000"
*DISP_RANGE_LOGCUTOFF "0.0100000000"
*DISP_RANGE_RIGHT "69.9900000000"
*DISP_RANGE_TOP "14370.0000000000"
*DISP_SCALE_MODE_Y "0.0000000000"
*DISP_TAB_NAME "Theta/2-Theta"
*DISP_TITLE_Y "Intensity"
*DISP_UNIT_Y "COUNTS"
*DISP_WINDOW_NAME "MSG_MACROENGINE"
*FILE_COMMENT " "
*FILE_MD5 ""
*FILE_MEMO " "
*FILE_OPERATOR "Administrator"
*FILE_PART_ID "MEAS_PBEA_00223"
*FILE_SAMPLE "NaCl"
*FILE_TYPE "RAS_RAW"
*FILE_USERGROUP "System Manager"
*FILE_VERSION "1.0000000000"
*HW_ATTACHMENT_ID "ATT1031"
*HW_ATTACHMENT_NAME "6サンプルチェンジャ|ASC-6"
*HW_COUNTER_ID-0 "CUT0021"
*HW_COUNTER_ID-1 "CUT0020"
*HW_COUNTER_ID-2 "CUT0020"
*HW_COUNTER_ID-3 "CMC0021"
*HW_COUNTER_NAME-0 "SC-70|SC-70"
*HW_COUNTER_NAME-1 "None|None"
*HW_COUNTER_NAME-2 "None|None"
*HW_COUNTER_NAME-3 "検出器モノクロメータ|Detector monochromator"
*HW_COUNTER_SELECT_NAME "SC-70|SC-70"
*HW_ECP_HV "714.0000000000"
*HW_ECP_HV_UNIT "V"
*HW_GONIOMETER_ID "GON0070"
*HW_GONIOMETER_NAME "MiniFlex 300/600|MiniFlex 300/600"
*HW_GONIOMETER_RADIUS-0 "79.0"
*HW_GONIOMETER_RADIUS-1 "91.5"
*HW_GONIOMETER_RADIUS-2 "150.0"
*HW_GONIOMETER_RADIUS-3 "0"
*HW_GONIOMETER_RADIUS-4 "103.4"
*HW_GONIOMETER_RADIUS-5 "150.0"
*HW_GONIOMETER_RADIUS-6 "46.6"
*HW_GONIOMETER_RADIUS-7 "160.0"
*HW_I_OPT_ID-0 "ISL0021"
*HW_I_OPT_ID-1 "ISO0021"
*HW_I_OPT_NAME-0 "発散スリット|Divergence slit"
*HW_I_OPT_NAME-1 "入射平行スリット|Incident parallel slit"
*HW_R_ATTENUATER_AUTOMODE "0"
*HW_R_OPT_ID-0 "RSS0021"
*HW_R_OPT_ID-1 "RSO0021"
*HW_R_OPT_ID-2 "RRS0021"
*HW_R_OPT_NAME-0 "散乱スリット|Scattering slit"
*HW_R_OPT_NAME-1 "受光平行スリット|Receiving soller slit"
*HW_R_OPT_NAME-2 "受光スリット|Receiving slit"
*HW_SAMPLE_HOLDER_ID "SMP0000"
*HW_SAMPLE_HOLDER_NAME "無し|None"
*HW_XG_CURRENT_MAX "50"
*HW_XG_CURRENT_MIN "2"
*HW_XG_CURRENT_RESOLUTION "2"
*HW_XG_CURRENT_UNIT "mA"
*HW_XG_FOCUS "1mm x 10mm"
*HW_XG_FOCUS_TYPE "Normal"
*HW_XG_ID "1062"
*HW_XG_NAME "300W/600W 封入管-A|300W/600W Sealed tube-A"
*HW_XG_TARGET_ATOMIC_NUMBER "29.0000000000"
*HW_XG_TARGET_NAME "Cu"
*HW_XG_TYPE "Compact"
*HW_XG_VOLTAGE_MAX "60"
*HW_XG_VOLTAGE_MIN "20"
*HW_XG_VOLTAGE_RESOLUTION "2"
*HW_XG_VOLTAGE_UNIT "kV"
*HW_XG_WATT_MAX "2.000"
*HW_XG_WATT_UNIT "kW"
*HW_XG_WAVE_LENGTH_ALPHA1 "1.540593"
*HW_XG_WAVE_LENGTH_ALPHA2 "1.544414"
*HW_XG_WAVE_LENGTH_BETA "1.392250"
*MEAS_COND_AXIS_NAME-0 "Theta/2-Theta"
*MEAS_COND_AXIS_NAME-1 "Spin"
*MEAS_COND_AXIS_NAME-2 "Change"
*MEAS_COND_AXIS_NAME-3 "Soller(inc.)"
*MEAS_COND_AXIS_NAME-4 "IHS"
*MEAS_COND_AXIS_NAME-5 "DS"
*MEAS_COND_AXIS_NAME-6 "SS"
*MEAS_COND_AXIS_NAME-7 "Soller(rec.)"
*MEAS_COND_AXIS_NAME-8 "RS"
*MEAS_COND_AXIS_NAME-9 "Filter"
*MEAS_COND_AXIS_NAME-10 "Monochromator"
*MEAS_COND_AXIS_NAME-11 "HV"
*MEAS_COND_AXIS_NAME-12 "PHA"
*MEAS_COND_AXIS_NAME_INTERNAL-0 "TwoThetaTheta"
*MEAS_COND_AXIS_NAME_INTERNAL-1 "Spin"
*MEAS_COND_AXIS_NAME_INTERNAL-2 "Change"
*MEAS_COND_AXIS_NAME_INTERNAL-3 "IncidentSollerSlit"
*MEAS_COND_AXIS_NAME_INTERNAL-4 "IncidentAxdSlit"
*MEAS_COND_AXIS_NAME_INTERNAL-5 "IncidentSlitBox"
*MEAS_COND_AXIS_NAME_INTERNAL-6 "ReceivingSlitBox1"
*MEAS_COND_AXIS_NAME_INTERNAL-7 "ReceivingSollerSlit"
*MEAS_COND_AXIS_NAME_INTERNAL-8 "ReceivingSlitBox2"
*MEAS_COND_AXIS_NAME_INTERNAL-9 "Filter"
*MEAS_COND_AXIS_NAME_INTERNAL-10 "CounterMonochromator"
*MEAS_COND_AXIS_NAME_INTERNAL-11 "HV"
*MEAS_COND_AXIS_NAME_INTERNAL-12 "PHA"
*MEAS_COND_AXIS_NAME_MAGICNO-0 "268632064.0000000000"
*MEAS_COND_AXIS_NAME_MAGICNO-1 "16842752.0000000000"
*MEAS_COND_AXIS_NAME_MAGICNO-2 "16842752.0000000000"
*MEAS_COND_AXIS_NAME_MAGICNO-3 "20971521.0000000000"
*MEAS_COND_AXIS_NAME_MAGICNO-4 "22020097.0000000000"
*MEAS_COND_AXIS_NAME_MAGICNO-5 "22020097.0000000000"
*MEAS_COND_AXIS_NAME_MAGICNO-6 "23068673.0000000000"
*MEAS_COND_AXIS_NAME_MAGICNO-7 "20971521.0000000000"
*MEAS_COND_AXIS_NAME_MAGICNO-8 "23068673.0000000000"
*MEAS_COND_AXIS_NAME_MAGICNO-9 "20971521.0000000000"
*MEAS_COND_AXIS_NAME_MAGICNO-10 "20971521.0000000000"
*MEAS_COND_AXIS_NAME_MAGICNO-11 "0.0000000000"
*MEAS_COND_AXIS_NAME_MAGICNO-12 "0.0000000000"
*MEAS_COND_AXIS_OFFSET-0 "0.0000000000"
*MEAS_COND_AXIS_OFFSET-1 "-"
*MEAS_COND_AXIS_OFFSET-2 "-"
*MEAS_COND_AXIS_OFFSET-3 "-"
*MEAS_COND_AXIS_OFFSET-4 "-"
*MEAS_COND_AXIS_OFFSET-5 "-"
*MEAS_COND_AXIS_OFFSET-6 "-"
*MEAS_COND_AXIS_OFFSET-7 "-"
*MEAS_COND_AXIS_OFFSET-8 "-"
*MEAS_COND_AXIS_OFFSET-9 "-"
*MEAS_COND_AXIS_OFFSET-10 "-"
*MEAS_COND_AXIS_OFFSET-11 "-"
*MEAS_COND_AXIS_OFFSET-12 "-"
*MEAS_COND_AXIS_POSITION-0 "10.0000000000"
*MEAS_COND_AXIS_POSITION-1 "0.0000000000"
*MEAS_COND_AXIS_POSITION-2 "3.0000000000"
*MEAS_COND_AXIS_POSITION-3 "2.5deg"
*MEAS_COND_AXIS_POSITION-4 "10.0mm"
*MEAS_COND_AXIS_POSITION-5 "1.250deg"
*MEAS_COND_AXIS_POSITION-6 "13.0mm(Open)"
*MEAS_COND_AXIS_POSITION-7 "5.0deg"
*MEAS_COND_AXIS_POSITION-8 "13.0mm"
*MEAS_COND_AXIS_POSITION-9 "None"
*MEAS_COND_AXIS_POSITION-10 "None"
*MEAS_COND_AXIS_POSITION-11 "714.0000000000"
*MEAS_COND_AXIS_POSITION-12 "568.7500000000"
*MEAS_COND_AXIS_UNIT-0 "deg"
*MEAS_COND_AXIS_UNIT-1 ""
*MEAS_COND_AXIS_UNIT-2 ""
*MEAS_COND_AXIS_UNIT-3 ""
*MEAS_COND_AXIS_UNIT-4 ""
*MEAS_COND_AXIS_UNIT-5 ""
*MEAS_COND_AXIS_UNIT-6 ""
*MEAS_COND_AXIS_UNIT-7 ""
*MEAS_COND_AXIS_UNIT-8 ""
*MEAS_COND_AXIS_UNIT-9 ""
*MEAS_COND_AXIS_UNIT-10 ""
*MEAS_COND_AXIS_UNIT-11 "V"
*MEAS_COND_AXIS_UNIT-12 "mV"
*MEAS_COND_CORRECTION_SLIT_COUNTERMONO "None"
*MEAS_COND_CORRECTION_SLIT_DS "1.250deg"
*MEAS_COND_CORRECTION_SLIT_FILTER "None"
*MEAS_COND_CORRECTION_SLIT_IHS "10.0mm"
*MEAS_COND_CORRECTION_SLIT_RS "13.0mm"
*MEAS_COND_CORRECTION_SLIT_SOLLER_INC "2.5deg"
*MEAS_COND_CORRECTION_SLIT_SOLLER_REC "5.0deg"
*MEAS_COND_CORRECTION_SLIT_SS "13.0mm"
*MEAS_COND_COUNTER_CNTLOSS_CORR "0.0000000000"
*MEAS_COND_COUNTER_PHABASE "568.7500000000"
*MEAS_COND_COUNTER_PHAWINDOW "926.2500000000"
*MEAS_COND_COUNTER_PHA_UNIT "mV"
*MEAS_COND_COUNTER_TAUDIFF "0.2500000000"
*MEAS_COND_COUNTER_TAUINT "0.7500000000"
*MEAS_COND_IRRADIATION_MODE "OFF"
*MEAS_COND_IRRADIATION_WIDTH ""
*MEAS_COND_OPT_ATTR " "
*MEAS_COND_OPT_NAME ""
*MEAS_COND_UNSYMMETRIC_MODE "OFF"
*MEAS_COND_XG_CURRENT "15.0000000000"
*MEAS_COND_XG_VOLTAGE "40.0000000000"
*MEAS_COND_XG_WAVE_TYPE "Ka"
*MEAS_DATA_COUNT "3400.0000000000"
*MEAS_SCAN_AXIS_X "Theta/2-Theta"
*MEAS_SCAN_AXIS_X_INTERNAL "TwoThetaTheta"
*MEAS_SCAN_END_TIME "02/21/25 11:41:57"
*MEAS_SCAN_MODE "CONTINUOUS"
*MEAS_SCAN_MONITOR "0"
*MEAS_SCAN_RESOLUTION_X "0.0025"
*MEAS_SCAN_SPEED "2.0000"
*MEAS_SCAN_SPEED_UNIT "deg/min"
*MEAS_SCAN_SPEED_USER "2.0000"
*MEAS_SCAN_START "2.0100000000"
*MEAS_SCAN_START_TIME "02/21/25 11:07:49"
*MEAS_SCAN_STEP "0.0200000000"
*MEAS_SCAN_STOP "69.9900000000"
*MEAS_SCAN_UNIT_X "deg"
*MEAS_SCAN_UNIT_Y "counts"
*SLIT_SYSTEM "0"
*RAS_HEADER_END
*RAS_INT_START
2.0100 706.0000 1.0000
2.0700 694.0000 1.0000
2.1300 692.0000 1.0000
2.1900 597.0000 1.0000
2.2500 697.0000 1.0000
2.3100 485.0000 1.0000
2.3700 449.0000 1.0000
2.4300 515.0000 1.0000
2.4900 502.0000 1.0000
2.5500 527.0000 1.0000
2.6100 637.0000 1.0000
2.6700 531.0000 1.0000
2.7300 479.0000 1.0000
2.7900 522.0000 1.0000
2.8500 465.0000 1.0000
2.9100 391.0000 1.0000
2.9700 321.0000 1.0000
3.0300 400.0000 1.0000
3.0900 375.0000 1.0000
3.1500 356.0000 1.0000
3.2100 326.0000 1.0000
3.2700 320.0000 1.0000
3.3300 325.0000 1.0000
3.3900 248.0000 1.0000
3.4500 260.0000 1.0000
3.5100 271.0000 1.0000
3.5700 246.0000 1.0000
3.6300 175.0000 1.0000
3.6900 243.0000 1.0000
3.7500 224.0000 1.0000
3.8100 235.0000 1.0000
3.8700 193.0000 1.0000
3.9300 204.0000 1.0000
3.9900 220.0000 1.0000
4.0500 189.0000 1.0000
4.1100 182.0000 1.0000
4.1700 188.0000 1.0000
4.2300 212.0000 1.0000
4.2900 165.0000 1.0000
4.3500 193.0000 1.0000
4.4100 135.0000 1.0000
4.4700 163.0000 1.0000
4.5300 214.0000 1.0000
4.5900 159.0000 1.0000
4.6500 157.0000 1.0000
4.7100 194.0000 1.0000
4.7700 145.0000 1.0000
4.8300 174.0000 1.0000
4.8900 134.0000 1.0000
4.9500 158.0000 1.0000
5.0100 179.0000 1.0000
5.0700 140.0000 1.0000
5.1300 127.0000 1.0000
5.1900 148.0000 1.0000
5.2500 135.0000 1.0000
5.3100 106.0000 1.0000
5.3700 104.0000 1.0000
5.4300 144.0000 1.0000
5.4900 109.0000 1.0000
5.5500 135.0000 1.0000
5.6100 140.0000 1.0000
5.6700 128.0000 1.0000
5.7300 160.0000 1.0000
5.7900 116.0000 1.0000
5.8500 147.0000 1.0000
5.9100 142.0000 1.0000
5.9700 156.0000 1.0000
6.0300 173.0000 1.0000
6.0900 135.0000 1.0000
6.1500 185.0000 1.0000
6.2100 180.0000 1.0000
6.2700 241.0000 1.0000
6.3300 198.0000 1.0000
6.3900 222.0000 1.0000
6.4500 264.0000 1.0000
6.5100 241.0000 1.0000
6.5700 267.0000 1.0000
6.6300 270.0000 1.0000
6.6900 229.0000 1.0000
6.7500 343.0000 1.0000
6.8100 291.0000 1.0000
6.8700 332.0000 1.0000
6.9300 364.0000 1.0000
6.9900 323.0000 1.0000
7.0500 286.0000 1.0000
7.1100 347.0000 1.0000
7.1700 362.0000 1.0000
7.2300 271.0000 1.0000
7.2900 287.0000 1.0000
7.3500 264.0000 1.0000
7.4100 265.0000 1.0000
7.4700 243.0000 1.0000
7.5300 186.0000 1.0000
7.5900 165.0000 1.0000
7.6500 68.0000 1.0000
7.7100 90.0000 1.0000
7.7700 101.0000 1.0000
7.8300 117.0000 1.0000
7.8900 76.0000 1.0000
7.9500 101.0000 1.0000
8.0100 84.0000 1.0000
8.0700 109.0000 1.0000
8.1300 71.0000 1.0000
8.1900 78.0000 1.0000
8.2500 102.0000 1.0000
8.3100 92.0000 1.0000
8.3700 89.0000 1.0000
8.4300 91.0000 1.0000
8.4900 106.0000 1.0000
8.5500 76.0000 1.0000
8.6100 52.0000 1.0000
8.6700 75.0000 1.0000
8.7300 68.0000 1.0000
8.7900 79.0000 1.0000
8.8500 87.0000 1.0000
8.9100 92.0000 1.0000
8.9700 94.0000 1.0000
9.0300 83.0000 1.0000
9.0900 90.0000 1.0000
9.1500 53.0000 1.0000
9.2100 87.0000 1.0000
9.2700 97.0000 1.0000
9.3300 108.0000 1.0000
9.3900 98.0000 1.0000
9.4500 79.0000 1.0000
9.5100 83.0000 1.0000
9.5700 88.0000 1.0000
9.6300 82.0000 1.0000
9.6900 116.0000 1.0000
9.7500 102.0000 1.0000
9.8100 69.0000 1.0000
9.8700 93.0000 1.0000
9.9300 66.0000 1.0000
9.9900 105.0000 1.0000
10.0500 69.0000 1.0000
10.1100 105.0000 1.0000
10.1700 92.0000 1.0000
10.2300 79.0000 1.0000
10.2900 96.0000 1.0000
10.3500 63.0000 1.0000
10.4100 81.0000 1.0000
10.4700 71.0000 1.0000
10.5300 71.0000 1.0000
10.5900 83.0000 1.0000
10.6500 81.0000 1.0000
10.7100 49.0000 1.0000
10.7700 66.0000 1.0000
10.8300 71.0000 1.0000
10.8900 76.0000 1.0000
10.9500 46.0000 1.0000
11.0100 54.0000 1.0000
11.0700 64.0000 1.0000
11.1300 47.0000 1.0000
11.1900 53.0000 1.0000
11.2500 71.0000 1.0000
11.3100 68.0000 1.0000
11.3700 72.0000 1.0000
11.4300 62.0000 1.0000
11.4900 54.0000 1.0000
11.5500 32.0000 1.0000
11.6100 72.0000 1.0000
11.6700 61.0000 1.0000
11.7300 62.0000 1.0000
11.7900 48.0000 1.0000
11.8500 55.0000 1.0000
11.9100 52.0000 1.0000
11.9700 52.0000 1.0000
12.0300 47.0000 1.0000
12.0900 51.0000 1.0000
12.1500 52.0000 1.0000
12.2100 60.0000 1.0000
12.2700 44.0000 1.0000
12.3300 67.0000 1.0000
12.3900 59.0000 1.0000
12.4500 54.0000 1.0000
12.5100 45.0000 1.0000
12.5700 63.0000 1.0000
12.6300 67.0000 1.0000
12.6900 56.0000 1.0000
12.7500 56.0000 1.0000
12.8100 44.0000 1.0000
12.8700 58.0000 1.0000
12.9300 41.0000 1.0000
12.9900 33.0000 1.0000
13.0500 54.0000 1.0000
13.1100 39.0000 1.0000
13.1700 55.0000 1.0000
13.2300 54.0000 1.0000
13.2900 51.0000 1.0000
13.3500 63.0000 1.0000
13.4100 68.0000 1.0000
13.4700 53.0000 1.0000
13.5300 51.0000 1.0000
13.5900 54.0000 1.0000
13.6500 51.0000 1.0000
13.7100 41.0000 1.0000
13.7700 49.0000 1.0000
13.8300 58.0000 1.0000
13.8900 49.0000 1.0000
13.9500 44.0000 1.0000
14.0100 59.0000 1.0000
14.0700 52.0000 1.0000
14.1300 49.0000 1.0000
14.1900 55.0000 1.0000
14.2500 60.0000 1.0000
14.3100 56.0000 1.0000
14.3700 51.0000 1.0000
14.4300 48.0000 1.0000
14.4900 66.0000 1.0000
14.5500 63.0000 1.0000
14.6100 53.0000 1.0000
14.6700 66.0000 1.0000
14.7300 62.0000 1.0000
14.7900 46.0000 1.0000
14.8500 52.0000 1.0000
14.9100 46.0000 1.0000
14.9700 51.0000 1.0000
15.0300 55.0000 1.0000
15.0900 60.0000 1.0000
15.1500 52.0000 1.0000
15.2100 55.0000 1.0000
15.2700 53.0000 1.0000
15.3300 60.0000 1.0000
15.3900 51.0000 1.0000
15.4500 48.0000 1.0000
15.5100 50.0000 1.0000
15.5700 59.0000 1.0000
15.6300 66.0000 1.0000
15.6900 69.0000 1.0000
15.7500 68.0000 1.0000
15.8100 53.0000 1.0000
15.8700 47.0000 1.0000
15.9300 61.0000 1.0000
15.9900 63.0000 1.0000
16.0500 67.0000 1.0000
16.1100 57.0000 1.0000
16.1700 68.0000 1.0000
16.2300 43.0000 1.0000
16.2900 48.0000 1.0000
16.3500 65.0000 1.0000
16.4100 56.0000 1.0000
16.4700 47.0000 1.0000
16.5300 44.0000 1.0000
16.5900 53.0000 1.0000
16.6500 57.0000 1.0000
16.7100 63.0000 1.0000
16.7700 58.0000 1.0000
16.8300 55.0000 1.0000
16.8900 49.0000 1.0000
16.9500 56.0000 1.0000
17.0100 58.0000 1.0000
17.0700 44.0000 1.0000
17.1300 54.0000 1.0000
17.1900 37.0000 1.0000
17.2500 50.0000 1.0000
17.3100 48.0000 1.0000
17.3700 67.0000 1.0000
17.4300 49.0000 1.0000
17.4900 41.0000 1.0000
17.5500 56.0000 1.0000
17.6100 45.0000 1.0000
17.6700 71.0000 1.0000
17.7300 37.0000 1.0000
17.7900 52.0000 1.0000
17.8500 40.0000 1.0000
17.9100 50.0000 1.0000
17.9700 36.0000 1.0000
18.0300 57.0000 1.0000
18.0900 57.0000 1.0000
18.1500 38.0000 1.0000
18.2100 56.0000 1.0000
18.2700 47.0000 1.0000
18.3300 45.0000 1.0000
18.3900 46.0000 1.0000
18.4500 36.0000 1.0000
18.5100 42.0000 1.0000
18.5700 45.0000 1.0000
18.6300 48.0000 1.0000
18.6900 33.0000 1.0000
18.7500 56.0000 1.0000
18.8100 46.0000 1.0000
18.8700 34.0000 1.0000
18.9300 49.0000 1.0000
18.9900 38.0000 1.0000
19.0500 52.0000 1.0000
19.1100 52.0000 1.0000
19.1700 44.0000 1.0000
19.2300 47.0000 1.0000
19.2900 39.0000 1.0000
19.3500 39.0000 1.0000
19.4100 28.0000 1.0000
19.4700 30.0000 1.0000
19.5300 47.0000 1.0000
19.5900 32.0000 1.0000
19.6500 37.0000 1.0000
19.7100 29.0000 1.0000
19.7700 34.0000 1.0000
19.8300 41.0000 1.0000
19.8900 36.0000 1.0000
19.9500 38.0000 1.0000
20.0100 38.0000 1.0000
20.0700 41.0000 1.0000
20.1300 47.0000 1.0000
20.1900 39.0000 1.0000
20.2500 37.0000 1.0000
20.3100 35.0000 1.0000
20.3700 43.0000 1.0000
20.4300 46.0000 1.0000
20.4900 38.0000 1.0000
20.5500 29.0000 1.0000
20.6100 31.0000 1.0000
20.6700 30.0000 1.0000
20.7300 38.0000 1.0000
20.7900 25.0000 1.0000
20.8500 41.0000 1.0000
20.9100 37.0000 1.0000
20.9700 41.0000 1.0000
21.0300 36.0000 1.0000
21.0900 49.0000 1.0000
21.1500 34.0000 1.0000
21.2100 38.0000 1.0000
21.2700 30.0000 1.0000
21.3300 39.0000 1.0000
21.3900 32.0000 1.0000
21.4500 30.0000 1.0000
21.5100 36.0000 1.0000
21.5700 23.0000 1.0000
21.6300 36.0000 1.0000
21.6900 25.0000 1.0000
21.7500 32.0000 1.0000
21.8100 28.0000 1.0000
21.8700 30.0000 1.0000
21.9300 28.0000 1.0000
21.9900 29.0000 1.0000
22.0500 32.0000 1.0000
22.1100 37.0000 1.0000
22.1700 37.0000 1.0000
22.2300 29.0000 1.0000
22.2900 24.0000 1.0000
22.3500 26.0000 1.0000
22.4100 40.0000 1.0000
22.4700 29.0000 1.0000
22.5300 31.0000 1.0000
22.5900 27.0000 1.0000
22.6500 24.0000 1.0000
22.7100 26.0000 1.0000
22.7700 22.0000 1.0000
22.8300 26.0000 1.0000
22.8900 27.0000 1.0000
22.9500 29.0000 1.0000
23.0100 24.0000 1.0000
23.0700 24.0000 1.0000
23.1300 30.0000 1.0000
23.1900 25.0000 1.0000
23.2500 23.0000 1.0000
23.3100 25.0000 1.0000
23.3700 21.0000 1.0000
23.4300 28.0000 1.0000
23.4900 23.0000 1.0000
23.5500 20.0000 1.0000
23.6100 23.0000 1.0000
23.6700 23.0000 1.0000
23.7300 18.0000 1.0000
23.7900 22.0000 1.0000
23.8500 15.0000 1.0000
23.9100 21.0000 1.0000
23.9700 19.0000 1.0000
24.0300 23.0000 1.0000
24.0900 25.0000 1.0000
24.1500 21.0000 1.0000
24.2100 26.0000 1.0000
24.2700 16.0000 1.0000
24.3300 30.0000 1.0000
24.3900 19.0000 1.0000
24.4500 12.0000 1.0000
24.5100 18.0000 1.0000
24.5700 13.0000 1.0000
24.6300 21.0000 1.0000
24.6900 24.0000 1.0000
24.7500 15.0000 1.0000
24.8100 31.0000 1.0000
24.8700 22.0000 1.0000
24.9300 19.0000 1.0000
24.9900 20.0000 1.0000
25.0500 22.0000 1.0000
25.1100 20.0000 1.0000
25.1700 25.0000 1.0000
25.2300 17.0000 1.0000
25.2900 17.0000 1.0000
25.3500 18.0000 1.0000
25.4100 17.0000 1.0000
25.4700 22.0000 1.0000
25.5300 22.0000 1.0000
25.5900 11.0000 1.0000
25.6500 18.0000 1.0000
25.7100 14.0000 1.0000
25.7700 16.0000 1.0000
25.8300 21.0000 1.0000
25.8900 10.0000 1.0000
25.9500 18.0000 1.0000
26.0100 14.0000 1.0000
26.0700 18.0000 1.0000
26.1300 22.0000 1.0000
26.1900 17.0000 1.0000
26.2500 18.0000 1.0000
26.3100 24.0000 1.0000
26.3700 30.0000 1.0000
26.4300 18.0000 1.0000
26.4900 12.0000 1.0000
26.5500 15.0000 1.0000
26.6100 19.0000 1.0000
26.6700 12.0000 1.0000
26.7300 22.0000 1.0000
26.7900 9.0000 1.0000
26.8500 10.0000 1.0000
26.9100 14.0000 1.0000
26.9700 16.0000 1.0000
27.0300 22.0000 1.0000
27.0900 20.0000 1.0000
27.1500 26.0000 1.0000
27.2100 42.0000 1.0000
27.2700 71.0000 1.0000
27.3300 97.0000 1.0000
27.3900 103.0000 1.0000
27.4500 66.0000 1.0000
27.5100 43.0000 1.0000
27.5700 18.0000 1.0000
27.6300 18.0000 1.0000
27.6900 18.0000 1.0000
27.7500 19.0000 1.0000
27.8100 19.0000 1.0000
27.8700 12.0000 1.0000
27.9300 22.0000 1.0000
27.9900 15.0000 1.0000
28.0500 20.0000 1.0000
28.1100 20.0000 1.0000
28.1700 14.0000 1.0000
28.2300 13.0000 1.0000
28.2900 21.0000 1.0000
28.3500 24.0000 1.0000
28.4100 14.0000 1.0000
28.4700 23.0000 1.0000
28.5300 50.0000 1.0000
28.5900 82.0000 1.0000
28.6500 103.0000 1.0000
28.7100 50.0000 1.0000
28.7700 26.0000 1.0000
28.8300 19.0000 1.0000
28.8900 12.0000 1.0000
28.9500 29.0000 1.0000
29.0100 22.0000 1.0000
29.0700 19.0000 1.0000
29.1300 13.0000 1.0000
29.1900 16.0000 1.0000
29.2500 18.0000 1.0000
29.3100 19.0000 1.0000
29.3700 13.0000 1.0000
29.4300 15.0000 1.0000
29.4900 17.0000 1.0000
29.5500 12.0000 1.0000
29.6100 18.0000 1.0000
29.6700 18.0000 1.0000
29.7300 13.0000 1.0000
29.7900 13.0000 1.0000
29.8500 23.0000 1.0000
29.9100 15.0000 1.0000
29.9700 20.0000 1.0000
30.0300 14.0000 1.0000
30.0900 9.0000 1.0000
30.1500 16.0000 1.0000
30.2100 18.0000 1.0000
30.2700 14.0000 1.0000
30.3300 11.0000 1.0000
30.3900 24.0000 1.0000
30.4500 18.0000 1.0000
30.5100 18.0000 1.0000
30.5700 37.0000 1.0000
30.6300 49.0000 1.0000
30.6900 60.0000 1.0000
30.7500 64.0000 1.0000
30.8100 67.0000 1.0000
30.8700 61.0000 1.0000
30.9300 74.0000 1.0000
30.9900 69.0000 1.0000
31.0500 73.0000 1.0000
31.1100 106.0000 1.0000
31.1700 125.0000 1.0000
31.2300 164.0000 1.0000
31.2900 204.0000 1.0000
31.3500 281.0000 1.0000
31.4100 307.0000 1.0000
31.4700 428.0000 1.0000
31.5300 549.0000 1.0000
31.5900 1333.0000 1.0000
31.6500 4277.0000 1.0000
31.7100 11048.0000 1.0000
31.7700 11220.0000 1.0000
31.8300 7500.0000 1.0000
31.8900 2559.0000 1.0000
31.9500 702.0000 1.0000
32.0100 332.0000 1.0000
32.0700 222.0000 1.0000
32.1300 139.0000 1.0000
32.1900 109.0000 1.0000
32.2500 77.0000 1.0000
32.3100 99.0000 1.0000
32.3700 69.0000 1.0000
32.4300 63.0000 1.0000
32.4900 65.0000 1.0000
32.5500 62.0000 1.0000
32.6100 73.0000 1.0000
32.6700 47.0000 1.0000
32.7300 49.0000 1.0000
32.7900 46.0000 1.0000
32.8500 51.0000 1.0000
32.9100 45.0000 1.0000
32.9700 47.0000 1.0000
33.0300 41.0000 1.0000
33.0900 55.0000 1.0000
33.1500 44.0000 1.0000
33.2100 55.0000 1.0000
33.2700 37.0000 1.0000
33.3300 38.0000 1.0000
33.3900 30.0000 1.0000
33.4500 41.0000 1.0000
33.5100 34.0000 1.0000
33.5700 37.0000 1.0000
33.6300 31.0000 1.0000
33.6900 34.0000 1.0000
33.7500 28.0000 1.0000
33.8100 26.0000 1.0000
33.8700 43.0000 1.0000
33.9300 32.0000 1.0000
33.9900 35.0000 1.0000
34.0500 32.0000 1.0000
34.1100 28.0000 1.0000
34.1700 34.0000 1.0000
34.2300 26.0000 1.0000
34.2900 29.0000 1.0000
34.3500 41.0000 1.0000
34.4100 38.0000 1.0000
34.4700 19.0000 1.0000
34.5300 31.0000 1.0000
34.5900 26.0000 1.0000
34.6500 31.0000 1.0000
34.7100 37.0000 1.0000
34.7700 20.0000 1.0000
34.8300 27.0000 1.0000
34.8900 29.0000 1.0000
34.9500 23.0000 1.0000
35.0100 28.0000 1.0000
35.0700 26.0000 1.0000
35.1300 33.0000 1.0000
35.1900 23.0000 1.0000
35.2500 22.0000 1.0000
35.3100 21.0000 1.0000
35.3700 21.0000 1.0000
35.4300 24.0000 1.0000
35.4900 23.0000 1.0000
35.5500 24.0000 1.0000
35.6100 31.0000 1.0000
35.6700 24.0000 1.0000
35.7300 32.0000 1.0000
35.7900 18.0000 1.0000
35.8500 26.0000 1.0000
35.9100 17.0000 1.0000
35.9700 25.0000 1.0000
36.0300 22.0000 1.0000
36.0900 21.0000 1.0000
36.1500 28.0000 1.0000
36.2100 24.0000 1.0000
36.2700 28.0000 1.0000
36.3300 20.0000 1.0000
36.3900 25.0000 1.0000
36.4500 22.0000 1.0000
36.5100 19.0000 1.0000
36.5700 11.0000 1.0000
36.6300 24.0000 1.0000
36.6900 26.0000 1.0000
36.7500 22.0000 1.0000
36.8100 15.0000 1.0000
36.8700 18.0000 1.0000
36.9300 26.0000 1.0000
36.9900 17.0000 1.0000
37.0500 19.0000 1.0000
37.1100 19.0000 1.0000
37.1700 11.0000 1.0000
37.2300 28.0000 1.0000
37.2900 17.0000 1.0000
37.3500 20.0000 1.0000
37.4100 18.0000 1.0000
37.4700 13.0000 1.0000
37.5300 22.0000 1.0000
37.5900 18.0000 1.0000
37.6500 19.0000 1.0000
37.7100 22.0000 1.0000
37.7700 10.0000 1.0000
37.8300 19.0000 1.0000
37.8900 20.0000 1.0000
37.9500 15.0000 1.0000
38.0100 31.0000 1.0000
38.0700 23.0000 1.0000
38.1300 13.0000 1.0000
38.1900 12.0000 1.0000
38.2500 13.0000 1.0000
38.3100 20.0000 1.0000
38.3700 8.0000 1.0000
38.4300 12.0000 1.0000
38.4900 21.0000 1.0000
38.5500 10.0000 1.0000
38.6100 16.0000 1.0000
38.6700 18.0000 1.0000
38.7300 19.0000 1.0000
38.7900 11.0000 1.0000
38.8500 18.0000 1.0000
38.9100 12.0000 1.0000
38.9700 8.0000 1.0000
39.0300 12.0000 1.0000
39.0900 10.0000 1.0000
39.1500 15.0000 1.0000
39.2100 12.0000 1.0000
39.2700 15.0000 1.0000
39.3300 10.0000 1.0000
39.3900 13.0000 1.0000
39.4500 16.0000 1.0000
39.5100 13.0000 1.0000
39.5700 20.0000 1.0000
39.6300 18.0000 1.0000
39.6900 10.0000 1.0000
39.7500 16.0000 1.0000
39.8100 17.0000 1.0000
39.8700 13.0000 1.0000
39.9300 15.0000 1.0000
39.9900 18.0000 1.0000
40.0500 10.0000 1.0000
40.1100 13.0000 1.0000
40.1700 13.0000 1.0000
40.2300 15.0000 1.0000
40.2900 10.0000 1.0000
40.3500 10.0000 1.0000
40.4100 15.0000 1.0000
40.4700 10.0000 1.0000
40.5300 12.0000 1.0000
40.5900 12.0000 1.0000
40.6500 15.0000 1.0000
40.7100 8.0000 1.0000
40.7700 15.0000 1.0000
40.8300 25.0000 1.0000
40.8900 18.0000 1.0000
40.9500 10.0000 1.0000
41.0100 14.0000 1.0000
41.0700 13.0000 1.0000
41.1300 7.0000 1.0000
41.1900 7.0000 1.0000
41.2500 9.0000 1.0000
41.3100 8.0000 1.0000
41.3700 5.0000 1.0000
41.4300 13.0000 1.0000
41.4900 9.0000 1.0000
41.5500 15.0000 1.0000
41.6100 12.0000 1.0000
41.6700 11.0000 1.0000
41.7300 17.0000 1.0000
41.7900 16.0000 1.0000
41.8500 11.0000 1.0000
41.9100 14.0000 1.0000
41.9700 17.0000 1.0000
42.0300 13.0000 1.0000
42.0900 14.0000 1.0000
42.1500 11.0000 1.0000
42.2100 13.0000 1.0000
42.2700 12.0000 1.0000
42.3300 11.0000 1.0000
42.3900 8.0000 1.0000
42.4500 9.0000 1.0000
42.5100 11.0000 1.0000
42.5700 6.0000 1.0000
42.6300 6.0000 1.0000
42.6900 15.0000 1.0000
42.7500 15.0000 1.0000
42.8100 5.0000 1.0000
42.8700 14.0000 1.0000
42.9300 2.0000 1.0000
42.9900 7.0000 1.0000
43.0500 12.0000 1.0000
43.1100 11.0000 1.0000
43.1700 7.0000 1.0000
43.2300 8.0000 1.0000
43.2900 14.0000 1.0000
43.3500 9.0000 1.0000
43.4100 16.0000 1.0000
43.4700 11.0000 1.0000
43.5300 16.0000 1.0000
43.5900 11.0000 1.0000
43.6500 9.0000 1.0000
43.7100 15.0000 1.0000
43.7700 22.0000 1.0000
43.8300 16.0000 1.0000
43.8900 20.0000 1.0000
43.9500 14.0000 1.0000
44.0100 24.0000 1.0000
44.0700 13.0000 1.0000
44.1300 19.0000 1.0000
44.1900 12.0000 1.0000
44.2500 15.0000 1.0000
44.3100 24.0000 1.0000
44.3700 10.0000 1.0000
44.4300 14.0000 1.0000
44.4900 17.0000 1.0000
44.5500 11.0000 1.0000
44.6100 13.0000 1.0000
44.6700 14.0000 1.0000
44.7300 12.0000 1.0000
44.7900 21.0000 1.0000
44.8500 16.0000 1.0000
44.9100 32.0000 1.0000
44.9700 49.0000 1.0000
45.0300 52.0000 1.0000
45.0900 52.0000 1.0000
45.1500 58.0000 1.0000
45.2100 82.0000 1.0000
45.2700 134.0000 1.0000
45.3300 412.0000 1.0000
45.3900 1011.0000 1.0000
45.4500 1156.0000 1.0000
45.5100 881.0000 1.0000
45.5700 625.0000 1.0000
45.6300 282.0000 1.0000
45.6900 112.0000 1.0000
45.7500 66.0000 1.0000
45.8100 53.0000 1.0000
45.8700 32.0000 1.0000
45.9300 21.0000 1.0000
45.9900 17.0000 1.0000
46.0500 15.0000 1.0000
46.1100 11.0000 1.0000
46.1700 10.0000 1.0000
46.2300 14.0000 1.0000
46.2900 11.0000 1.0000
46.3500 14.0000 1.0000
46.4100 13.0000 1.0000
46.4700 9.0000 1.0000
46.5300 13.0000 1.0000
46.5900 8.0000 1.0000
46.6500 14.0000 1.0000
46.7100 12.0000 1.0000
46.7700 10.0000 1.0000
46.8300 9.0000 1.0000
46.8900 13.0000 1.0000
46.9500 12.0000 1.0000
47.0100 11.0000 1.0000
47.0700 7.0000 1.0000
47.1300 16.0000 1.0000
47.1900 14.0000 1.0000
47.2500 9.0000 1.0000
47.3100 8.0000 1.0000
47.3700 9.0000 1.0000
47.4300 8.0000 1.0000
47.4900 12.0000 1.0000
47.5500 13.0000 1.0000
47.6100 7.0000 1.0000
47.6700 16.0000 1.0000
47.7300 5.0000 1.0000
47.7900 12.0000 1.0000
47.8500 10.0000 1.0000
47.9100 6.0000 1.0000
47.9700 9.0000 1.0000
48.0300 12.0000 1.0000
48.0900 6.0000 1.0000
48.1500 6.0000 1.0000
48.2100 16.0000 1.0000
48.2700 12.0000 1.0000
48.3300 14.0000 1.0000
48.3900 12.0000 1.0000
48.4500 13.0000 1.0000
48.5100 8.0000 1.0000
48.5700 11.0000 1.0000
48.6300 8.0000 1.0000
48.6900 10.0000 1.0000
48.7500 15.0000 1.0000
48.8100 11.0000 1.0000
48.8700 9.0000 1.0000
48.9300 12.0000 1.0000
48.9900 5.0000 1.0000
49.0500 5.0000 1.0000
49.1100 11.0000 1.0000
49.1700 7.0000 1.0000
49.2300 7.0000 1.0000
49.2900 9.0000 1.0000
49.3500 7.0000 1.0000
49.4100 9.0000 1.0000
49.4700 6.0000 1.0000
49.5300 8.0000 1.0000
49.5900 6.0000 1.0000
49.6500 3.0000 1.0000
49.7100 11.0000 1.0000
49.7700 10.0000 1.0000
49.8300 4.0000 1.0000
49.8900 7.0000 1.0000
49.9500 12.0000 1.0000
50.0100 8.0000 1.0000
50.0700 12.0000 1.0000
50.1300 10.0000 1.0000
50.1900 8.0000 1.0000
50.2500 6.0000 1.0000
50.3100 6.0000 1.0000
50.3700 8.0000 1.0000
50.4300 10.0000 1.0000
50.4900 6.0000 1.0000
50.5500 8.0000 1.0000
50.6100 12.0000 1.0000
50.6700 10.0000 1.0000
50.7300 5.0000 1.0000
50.7900 9.0000 1.0000
50.8500 9.0000 1.0000
50.9100 6.0000 1.0000
50.9700 10.0000 1.0000
51.0300 6.0000 1.0000
51.0900 6.0000 1.0000
51.1500 7.0000 1.0000
51.2100 7.0000 1.0000
51.2700 5.0000 1.0000
51.3300 9.0000 1.0000
51.3900 12.0000 1.0000
51.4500 13.0000 1.0000
51.5100 5.0000 1.0000
51.5700 7.0000 1.0000
51.6300 5.0000 1.0000
51.6900 9.0000 1.0000
51.7500 5.0000 1.0000
51.8100 7.0000 1.0000
51.8700 9.0000 1.0000
51.9300 7.0000 1.0000
51.9900 9.0000 1.0000
52.0500 6.0000 1.0000
52.1100 6.0000 1.0000
52.1700 6.0000 1.0000
52.2300 7.0000 1.0000
52.2900 6.0000 1.0000
52.3500 7.0000 1.0000
52.4100 3.0000 1.0000
52.4700 10.0000 1.0000
52.5300 8.0000 1.0000
52.5900 5.0000 1.0000
52.6500 4.0000 1.0000
52.7100 4.0000 1.0000
52.7700 6.0000 1.0000
52.8300 10.0000 1.0000
52.8900 11.0000 1.0000
52.9500 7.0000 1.0000
53.0100 7.0000 1.0000
53.0700 7.0000 1.0000
53.1300 4.0000 1.0000
53.1900 5.0000 1.0000
53.2500 9.0000 1.0000
53.3100 2.0000 1.0000
53.3700 8.0000 1.0000
53.4300 9.0000 1.0000
53.4900 1.0000 1.0000
53.5500 10.0000 1.0000
53.6100 4.0000 1.0000
53.6700 10.0000 1.0000
53.7300 20.0000 1.0000
53.7900 31.0000 1.0000
53.8500 24.0000 1.0000
53.9100 31.0000 1.0000
53.9700 25.0000 1.0000
54.0300 14.0000 1.0000
54.0900 11.0000 1.0000
54.1500 12.0000 1.0000
54.2100 8.0000 1.0000
54.2700 9.0000 1.0000
54.3300 9.0000 1.0000
54.3900 7.0000 1.0000
54.4500 7.0000 1.0000
54.5100 9.0000 1.0000
54.5700 6.0000 1.0000
54.6300 5.0000 1.0000
54.6900 9.0000 1.0000
54.7500 12.0000 1.0000
54.8100 5.0000 1.0000
54.8700 7.0000 1.0000
54.9300 9.0000 1.0000
54.9900 6.0000 1.0000
55.0500 7.0000 1.0000
55.1100 9.0000 1.0000
55.1700 6.0000 1.0000
55.2300 5.0000 1.0000
55.2900 4.0000 1.0000
55.3500 8.0000 1.0000
55.4100 7.0000 1.0000
55.4700 14.0000 1.0000
55.5300 4.0000 1.0000
55.5900 8.0000 1.0000
55.6500 6.0000 1.0000
55.7100 7.0000 1.0000
55.7700 9.0000 1.0000
55.8300 7.0000 1.0000
55.8900 11.0000 1.0000
55.9500 11.0000 1.0000
56.0100 20.0000 1.0000
56.0700 9.0000 1.0000
56.1300 15.0000 1.0000
56.1900 20.0000 1.0000
56.2500 25.0000 1.0000
56.3100 75.0000 1.0000
56.3700 85.0000 1.0000
56.4300 107.0000 1.0000
56.4900 111.0000 1.0000
56.5500 80.0000 1.0000
56.6100 53.0000 1.0000
56.6700 36.0000 1.0000
56.7300 20.0000 1.0000
56.7900 13.0000 1.0000
56.8500 7.0000 1.0000
56.9100 9.0000 1.0000
56.9700 13.0000 1.0000
57.0300 9.0000 1.0000
57.0900 12.0000 1.0000
57.1500 7.0000 1.0000
57.2100 6.0000 1.0000
57.2700 7.0000 1.0000
57.3300 5.0000 1.0000
57.3900 7.0000 1.0000
57.4500 5.0000 1.0000
57.5100 6.0000 1.0000
57.5700 5.0000 1.0000
57.6300 6.0000 1.0000
57.6900 2.0000 1.0000
57.7500 4.0000 1.0000
57.8100 15.0000 1.0000
57.8700 5.0000 1.0000
57.9300 8.0000 1.0000
57.9900 6.0000 1.0000
58.0500 4.0000 1.0000
58.1100 7.0000 1.0000
58.1700 6.0000 1.0000
58.2300 5.0000 1.0000
58.2900 3.0000 1.0000
58.3500 6.0000 1.0000
58.4100 5.0000 1.0000
58.4700 7.0000 1.0000
58.5300 8.0000 1.0000
58.5900 4.0000 1.0000
58.6500 7.0000 1.0000
58.7100 6.0000 1.0000
58.7700 5.0000 1.0000
58.8300 10.0000 1.0000
58.8900 2.0000 1.0000
58.9500 6.0000 1.0000
59.0100 6.0000 1.0000
59.0700 8.0000 1.0000
59.1300 14.0000 1.0000
59.1900 11.0000 1.0000
59.2500 8.0000 1.0000
59.3100 6.0000 1.0000
59.3700 4.0000 1.0000
59.4300 4.0000 1.0000
59.4900 4.0000 1.0000
59.5500 7.0000 1.0000
59.6100 4.0000 1.0000
59.6700 5.0000 1.0000
59.7300 1.0000 1.0000
59.7900 8.0000 1.0000
59.8500 6.0000 1.0000
59.9100 9.0000 1.0000
59.9700 10.0000 1.0000
60.0300 5.0000 1.0000
60.0900 9.0000 1.0000
60.1500 5.0000 1.0000
60.2100 9.0000 1.0000
60.2700 8.0000 1.0000
60.3300 9.0000 1.0000
60.3900 3.0000 1.0000
60.4500 8.0000 1.0000
60.5100 7.0000 1.0000
60.5700 4.0000 1.0000
60.6300 6.0000 1.0000
60.6900 9.0000 1.0000
60.7500 4.0000 1.0000
60.8100 6.0000 1.0000
60.8700 7.0000 1.0000
60.9300 8.0000 1.0000
60.9900 4.0000 1.0000
61.0500 3.0000 1.0000
61.1100 3.0000 1.0000
61.1700 7.0000 1.0000
61.2300 7.0000 1.0000
61.2900 6.0000 1.0000
61.3500 7.0000 1.0000
61.4100 8.0000 1.0000
61.4700 6.0000 1.0000
61.5300 6.0000 1.0000
61.5900 5.0000 1.0000
61.6500 6.0000 1.0000
61.7100 5.0000 1.0000
61.7700 3.0000 1.0000
61.8300 7.0000 1.0000
61.8900 6.0000 1.0000
61.9500 7.0000 1.0000
62.0100 7.0000 1.0000
62.0700 7.0000 1.0000
62.1300 8.0000 1.0000
62.1900 5.0000 1.0000
62.2500 5.0000 1.0000
62.3100 2.0000 1.0000
62.3700 9.0000 1.0000
62.4300 10.0000 1.0000
62.4900 4.0000 1.0000
62.5500 6.0000 1.0000
62.6100 5.0000 1.0000
62.6700 5.0000 1.0000
62.7300 5.0000 1.0000
62.7900 5.0000 1.0000
62.8500 5.0000 1.0000
62.9100 3.0000 1.0000
62.9700 4.0000 1.0000
63.0300 5.0000 1.0000
63.0900 9.0000 1.0000
63.1500 8.0000 1.0000
63.2100 9.0000 1.0000
63.2700 10.0000 1.0000
63.3300 8.0000 1.0000
63.3900 6.0000 1.0000
63.4500 7.0000 1.0000
63.5100 9.0000 1.0000
63.5700 13.0000 1.0000
63.6300 7.0000 1.0000
63.6900 6.0000 1.0000
63.7500 9.0000 1.0000
63.8100 8.0000 1.0000
63.8700 10.0000 1.0000
63.9300 7.0000 1.0000
63.9900 8.0000 1.0000
64.0500 3.0000 1.0000
64.1100 4.0000 1.0000
64.1700 4.0000 1.0000
64.2300 10.0000 1.0000
64.2900 4.0000 1.0000
64.3500 4.0000 1.0000
64.4100 10.0000 1.0000
64.4700 8.0000 1.0000
64.5300 5.0000 1.0000
64.5900 9.0000 1.0000
64.6500 13.0000 1.0000
64.7100 8.0000 1.0000
64.7700 12.0000 1.0000
64.8300 13.0000 1.0000
64.8900 9.0000 1.0000
64.9500 12.0000 1.0000
65.0100 6.0000 1.0000
65.0700 10.0000 1.0000
65.1300 7.0000 1.0000
65.1900 7.0000 1.0000
65.2500 9.0000 1.0000
65.3100 10.0000 1.0000
65.3700 14.0000 1.0000
65.4300 9.0000 1.0000
65.4900 10.0000 1.0000
65.5500 17.0000 1.0000
65.6100 10.0000 1.0000
65.6700 11.0000 1.0000
65.7300 12.0000 1.0000
65.7900 20.0000 1.0000
65.8500 17.0000 1.0000
65.9100 23.0000 1.0000
65.9700 34.0000 1.0000
66.0300 49.0000 1.0000
66.0900 133.0000 1.0000
66.1500 258.0000 1.0000
66.2100 320.0000 1.0000
66.2700 292.0000 1.0000
66.3300 257.0000 1.0000
66.3900 196.0000 1.0000
66.4500 155.0000 1.0000
66.5100 89.0000 1.0000
66.5700 27.0000 1.0000
66.6300 16.0000 1.0000
66.6900 15.0000 1.0000
66.7500 13.0000 1.0000
66.8100 9.0000 1.0000
66.8700 12.0000 1.0000
66.9300 13.0000 1.0000
66.9900 18.0000 1.0000
67.0500 12.0000 1.0000
67.1100 16.0000 1.0000
67.1700 9.0000 1.0000
67.2300 9.0000 1.0000
67.2900 8.0000 1.0000
67.3500 6.0000 1.0000
67.4100 13.0000 1.0000
67.4700 10.0000 1.0000
67.5300 8.0000 1.0000
67.5900 8.0000 1.0000
67.6500 7.0000 1.0000
67.7100 7.0000 1.0000
67.7700 8.0000 1.0000
67.8300 12.0000 1.0000
67.8900 9.0000 1.0000
67.9500 8.0000 1.0000
68.0100 5.0000 1.0000
68.0700 6.0000 1.0000
68.1300 7.0000 1.0000
68.1900 6.0000 1.0000
68.2500 5.0000 1.0000
68.3100 9.0000 1.0000
68.3700 6.0000 1.0000
68.4300 7.0000 1.0000
68.4900 10.0000 1.0000
68.5500 7.0000 1.0000
68.6100 13.0000 1.0000
68.6700 6.0000 1.0000
68.7300 7.0000 1.0000
68.7900 0.0000 1.0000
68.8500 3.0000 1.0000
68.9100 5.0000 1.0000
68.9700 9.0000 1.0000
69.0300 7.0000 1.0000
69.0900 6.0000 1.0000
69.1500 15.0000 1.0000
69.2100 9.0000 1.0000
69.2700 4.0000 1.0000
69.3300 13.0000 1.0000
69.3900 2.0000 1.0000
69.4500 7.0000 1.0000
69.5100 6.0000 1.0000
69.5700 9.0000 1.0000
69.6300 11.0000 1.0000
69.6900 9.0000 1.0000
69.7500 1.0000 1.0000
69.8100 7.0000 1.0000
69.8700 1.0000 1.0000
69.9300 8.0000 1.0000
69.9900 6.0000 1.0000
*RAS_INT_END
*RAS_DATA_END